[{"TimeUTC":"2024-12-19 04:54:55","timestampInMs":1734584095164,"requestPath":"insta-analysis.vercel.app/","requestMethod":"GET","responseStatusCode":-1,"requestId":"vz2mt-1734584093388-1c66c45cecc0","requestUserAgent":"Mozilla/5.0 (Macintosh; Intel Mac OS X 10_15_7) AppleWebKit/537.36 (KHTML, like Gecko) Chrome/131.0.0.0 Safari/537.36","level":"error","environment":"production","branch":"main","vercelCache":"MISS","type":"lambda","function":"/api/index.py","host":"insta-analysis.vercel.app","deploymentDomain":"insta-analysis.vercel.app","deploymentId":"dpl_GQ3GJcyTnQmKqVYxKjT9F1rXMZ7B","durationMs":-1,"region":"iad1","maxMemoryUsed":-1,"memorySize":-1,"message":"ERROR:api.index:Import 오류: cannot import name 'OpenAI' from 'openai' (/var/task/openai/__init__.py)\nERROR:api.index:현재 Python 경로: ['/var/task', '/var/lang/lib/python312.zip', '/var/lang/lib/python3.12', '/var/lang/lib/python3.12/lib-dynload', '/var/lang/lib/python3.12/site-packages']\nTraceback (most recent call last):\nFile \"/var/task/vc__handler__python.py\", line 14, in <module>\n__vc_spec.loader.exec_module(__vc_module)\nFile \"<frozen importlib._bootstrap_external>\", line 995, in exec_module\nFile \"<frozen importlib._bootstrap>\", line 488, in _call_with_frames_removed\nFile \"/var/task/api/index.py\", line 20, in <module>\nfrom analysis.analyzer import ContentAnalyzer\nFile \"/var/task/analysis/analyzer.py\", line 3, in <module>\nfrom openai import OpenAI\nImportError: cannot import name 'OpenAI' from 'openai' (/var/task/openai/__init__.py)\nPython process exited with exit status: 1. The logs above can help with debugging the issue.","projectId":"prj_pdXNpNzcyIALXwyQJfTG9C9mLb6c"},{"TimeUTC":"2024-12-19 04:54:53","timestampInMs":1734584093689,"requestPath":"insta-analysis.vercel.app/","requestMethod":"GET","responseStatusCode":500,"requestId":"vz2mt-1734584093388-1c66c45cecc0","requestUserAgent":"Mozilla/5.0 (Macintosh; Intel Mac OS X 10_15_7) AppleWebKit/537.36 (KHTML, like Gecko) Chrome/131.0.0.0 Safari/537.36","level":"error","environment":"production","branch":"main","vercelCache":"MISS","type":"lambda","function":"/api/index.py","host":"insta-analysis.vercel.app","deploymentDomain":"insta-analysis.vercel.app","deploymentId":"dpl_GQ3GJcyTnQmKqVYxKjT9F1rXMZ7B","durationMs":1461,"region":"iad1","maxMemoryUsed":73,"memorySize":1024,"message":"","projectId":"prj_pdXNpNzcyIALXwyQJfTG9C9mLb6c"},{"TimeUTC":"2024-12-19 04:54:41","timestampInMs":1734584081400,"requestPath":"insta-analysis-d0u1o4xu8-hyunils-projects.vercel.app/favicon.png","requestMethod":"GET","responseStatusCode":-1,"requestId":"tsxmz-1734584079901-59104756402f","requestUserAgent":"Mozilla/5.0 (iPhone; CPU iPhone OS 18_0 like Mac OS X) AppleWebKit/605.1.15 (KHTML, like Gecko) Version/18.0 Mobile/15E148 Safari/604.1","level":"error","environment":"production","branch":"main","vercelCache":"MISS","type":"lambda","function":"/api/index.py","host":"insta-analysis-d0u1o4xu8-hyunils-projects.vercel.app","deploymentDomain":"insta-analysis-d0u1o4xu8-hyunils-projects.vercel.app","deploymentId":"dpl_GQ3GJcyTnQmKqVYxKjT9F1rXMZ7B","durationMs":-1,"region":"iad1","maxMemoryUsed":-1,"memorySize":-1,"message":"ERROR:api.index:Import 오류: cannot import name 'OpenAI' from 'openai' (/var/task/openai/__init__.py)\nERROR:api.index:현재 Python 경로: ['/var/task', '/var/lang/lib/python312.zip', '/var/lang/lib/python3.12', '/var/lang/lib/python3.12/lib-dynload', '/var/lang/lib/python3.12/site-packages']\nTraceback (most recent call last):\nFile \"/var/task/vc__handler__python.py\", line 14, in <module>\n__vc_spec.loader.exec_module(__vc_module)\nFile \"<frozen importlib._bootstrap_external>\", line 995, in exec_module\nFile \"<frozen importlib._bootstrap>\", line 488, in _call_with_frames_removed\nFile \"/var/task/api/index.py\", line 20, in <module>\nfrom analysis.analyzer import ContentAnalyzer\nFile \"/var/task/analysis/analyzer.py\", line 3, in <module>\nfrom openai import OpenAI\nImportError: cannot import name 'OpenAI' from 'openai' (/var/task/openai/__init__.py)\nPython process exited with exit status: 1. The logs above can help with debugging the issue.","projectId":"prj_pdXNpNzcyIALXwyQJfTG9C9mLb6c"},{"TimeUTC":"2024-12-19 04:54:39","timestampInMs":1734584079943,"requestPath":"insta-analysis-d0u1o4xu8-hyunils-projects.vercel.app/favicon.png","requestMethod":"GET","responseStatusCode":500,"requestId":"tsxmz-1734584079901-59104756402f","requestUserAgent":"Mozilla/5.0 (iPhone; CPU iPhone OS 18_0 like Mac OS X) AppleWebKit/605.1.15 (KHTML, like Gecko) Version/18.0 Mobile/15E148 Safari/604.1","level":"error","environment":"production","branch":"main","vercelCache":"MISS","type":"lambda","function":"/api/index.py","host":"insta-analysis-d0u1o4xu8-hyunils-projects.vercel.app","deploymentDomain":"insta-analysis-d0u1o4xu8-hyunils-projects.vercel.app","deploymentId":"dpl_GQ3GJcyTnQmKqVYxKjT9F1rXMZ7B","durationMs":1441,"region":"iad1","maxMemoryUsed":74,"memorySize":1024,"message":"","projectId":"prj_pdXNpNzcyIALXwyQJfTG9C9mLb6c"},{"TimeUTC":"2024-12-19 04:54:37","timestampInMs":1734584077777,"requestPath":"insta-analysis-d0u1o4xu8-hyunils-projects.vercel.app/favicon.png","requestMethod":"GET","responseStatusCode":-1,"requestId":"lg6ps-1734584076273-bcdfecaea6dd","requestUserAgent":"Mozilla/5.0 (iPhone; CPU iPhone OS 18_0 like Mac OS X) AppleWebKit/605.1.15 (KHTML, like Gecko) Version/18.0 Mobile/15E148 Safari/604.1","level":"error","environment":"production","branch":"main","vercelCache":"MISS","type":"lambda","function":"/api/index.py","host":"insta-analysis-d0u1o4xu8-hyunils-projects.vercel.app","deploymentDomain":"insta-analysis-d0u1o4xu8-hyunils-projects.vercel.app","deploymentId":"dpl_GQ3GJcyTnQmKqVYxKjT9F1rXMZ7B","durationMs":-1,"region":"iad1","maxMemoryUsed":-1,"memorySize":-1,"message":"ERROR:api.index:Import 오류: cannot import name 'OpenAI' from 'openai' (/var/task/openai/__init__.py)\nERROR:api.index:현재 Python 경로: ['/var/task', '/var/lang/lib/python312.zip', '/var/lang/lib/python3.12', '/var/lang/lib/python3.12/lib-dynload', '/var/lang/lib/python3.12/site-packages']\nTraceback (most recent call last):\nFile \"/var/task/vc__handler__python.py\", line 14, in <module>\n__vc_spec.loader.exec_module(__vc_module)\nFile \"<frozen importlib._bootstrap_external>\", line 995, in exec_module\nFile \"<frozen importlib._bootstrap>\", line 488, in _call_with_frames_removed\nFile \"/var/task/api/index.py\", line 20, in <module>\nfrom analysis.analyzer import ContentAnalyzer\nFile \"/var/task/analysis/analyzer.py\", line 3, in <module>\nfrom openai import OpenAI\nImportError: cannot import name 'OpenAI' from 'openai' (/var/task/openai/__init__.py)\nPython process exited with exit status: 1. The logs above can help with debugging the issue.","projectId":"prj_pdXNpNzcyIALXwyQJfTG9C9mLb6c"},{"TimeUTC":"2024-12-19 04:54:36","timestampInMs":1734584076314,"requestPath":"insta-analysis-d0u1o4xu8-hyunils-projects.vercel.app/favicon.png","requestMethod":"GET","responseStatusCode":500,"requestId":"lg6ps-1734584076273-bcdfecaea6dd","requestUserAgent":"Mozilla/5.0 (iPhone; CPU iPhone OS 18_0 like Mac OS X) AppleWebKit/605.1.15 (KHTML, like Gecko) Version/18.0 Mobile/15E148 Safari/604.1","level":"error","environment":"production","branch":"main","vercelCache":"MISS","type":"lambda","function":"/api/index.py","host":"insta-analysis-d0u1o4xu8-hyunils-projects.vercel.app","deploymentDomain":"insta-analysis-d0u1o4xu8-hyunils-projects.vercel.app","deploymentId":"dpl_GQ3GJcyTnQmKqVYxKjT9F1rXMZ7B","durationMs":1446,"region":"iad1","maxMemoryUsed":74,"memorySize":1024,"message":"","projectId":"prj_pdXNpNzcyIALXwyQJfTG9C9mLb6c"},{"TimeUTC":"2024-12-19 04:54:35","timestampInMs":1734584075159,"requestPath":"insta-analysis-d0u1o4xu8-hyunils-projects.vercel.app/favicon.png","requestMethod":"GET","responseStatusCode":-1,"requestId":"zd5gg-1734584073651-556742b35934","requestUserAgent":"Mozilla/5.0 (iPhone; CPU iPhone OS 18_0 like Mac OS X) AppleWebKit/605.1.15 (KHTML, like Gecko) Version/18.0 Mobile/15E148 Safari/604.1","level":"error","environment":"production","branch":"main","vercelCache":"MISS","type":"lambda","function":"/api/index.py","host":"insta-analysis-d0u1o4xu8-hyunils-projects.vercel.app","deploymentDomain":"insta-analysis-d0u1o4xu8-hyunils-projects.vercel.app","deploymentId":"dpl_GQ3GJcyTnQmKqVYxKjT9F1rXMZ7B","durationMs":-1,"region":"iad1","maxMemoryUsed":-1,"memorySize":-1,"message":"ERROR:api.index:Import 오류: cannot import name 'OpenAI' from 'openai' (/var/task/openai/__init__.py)\nERROR:api.index:현재 Python 경로: ['/var/task', '/var/lang/lib/python312.zip', '/var/lang/lib/python3.12', '/var/lang/lib/python3.12/lib-dynload', '/var/lang/lib/python3.12/site-packages']\nTraceback (most recent call last):\nFile \"/var/task/vc__handler__python.py\", line 14, in <module>\n__vc_spec.loader.exec_module(__vc_module)\nFile \"<frozen importlib._bootstrap_external>\", line 995, in exec_module\nFile \"<frozen importlib._bootstrap>\", line 488, in _call_with_frames_removed\nFile \"/var/task/api/index.py\", line 20, in <module>\nfrom analysis.analyzer import ContentAnalyzer\nFile \"/var/task/analysis/analyzer.py\", line 3, in <module>\nfrom openai import OpenAI\nImportError: cannot import name 'OpenAI' from 'openai' (/var/task/openai/__init__.py)\nPython process exited with exit status: 1. The logs above can help with debugging the issue.","projectId":"prj_pdXNpNzcyIALXwyQJfTG9C9mLb6c"},{"TimeUTC":"2024-12-19 04:54:34","timestampInMs":1734584074627,"requestPath":"insta-analysis-d0u1o4xu8-hyunils-projects.vercel.app/favicon.ico","requestMethod":"GET","responseStatusCode":-1,"requestId":"xlx4v-1734584073031-4d07e09b62ec","requestUserAgent":"Mozilla/5.0 (Macintosh; Intel Mac OS X 10_15_7) AppleWebKit/537.36 (KHTML, like Gecko) Chrome/131.0.0.0 Safari/537.36","level":"error","environment":"production","branch":"main","vercelCache":"MISS","type":"lambda","function":"/api/index.py","host":"insta-analysis-d0u1o4xu8-hyunils-projects.vercel.app","deploymentDomain":"insta-analysis-d0u1o4xu8-hyunils-projects.vercel.app","deploymentId":"dpl_GQ3GJcyTnQmKqVYxKjT9F1rXMZ7B","durationMs":-1,"region":"iad1","maxMemoryUsed":-1,"memorySize":-1,"message":"ERROR:api.index:Import 오류: cannot import name 'OpenAI' from 'openai' (/var/task/openai/__init__.py)\nERROR:api.index:현재 Python 경로: ['/var/task', '/var/lang/lib/python312.zip', '/var/lang/lib/python3.12', '/var/lang/lib/python3.12/lib-dynload', '/var/lang/lib/python3.12/site-packages']\nTraceback (most recent call last):\nFile \"/var/task/vc__handler__python.py\", line 14, in <module>\n__vc_spec.loader.exec_module(__vc_module)\nFile \"<frozen importlib._bootstrap_external>\", line 995, in exec_module\nFile \"<frozen importlib._bootstrap>\", line 488, in _call_with_frames_removed\nFile \"/var/task/api/index.py\", line 20, in <module>\nfrom analysis.analyzer import ContentAnalyzer\nFile \"/var/task/analysis/analyzer.py\", line 3, in <module>\nfrom openai import OpenAI\nImportError: cannot import name 'OpenAI' from 'openai' (/var/task/openai/__init__.py)\nPython process exited with exit status: 1. The logs above can help with debugging the issue.","projectId":"prj_pdXNpNzcyIALXwyQJfTG9C9mLb6c"},{"TimeUTC":"2024-12-19 04:54:33","timestampInMs":1734584073690,"requestPath":"insta-analysis-d0u1o4xu8-hyunils-projects.vercel.app/favicon.png","requestMethod":"GET","responseStatusCode":500,"requestId":"zd5gg-1734584073651-556742b35934","requestUserAgent":"Mozilla/5.0 (iPhone; CPU iPhone OS 18_0 like Mac OS X) AppleWebKit/605.1.15 (KHTML, like Gecko) Version/18.0 Mobile/15E148 Safari/604.1","level":"error","environment":"production","branch":"main","vercelCache":"MISS","type":"lambda","function":"/api/index.py","host":"insta-analysis-d0u1o4xu8-hyunils-projects.vercel.app","deploymentDomain":"insta-analysis-d0u1o4xu8-hyunils-projects.vercel.app","deploymentId":"dpl_GQ3GJcyTnQmKqVYxKjT9F1rXMZ7B","durationMs":1454,"region":"iad1","maxMemoryUsed":74,"memorySize":1024,"message":"","projectId":"prj_pdXNpNzcyIALXwyQJfTG9C9mLb6c"},{"TimeUTC":"2024-12-19 04:54:33","timestampInMs":1734584073565,"requestPath":"insta-analysis-d0u1o4xu8-hyunils-projects.vercel.app/favicon.ico","requestMethod":"GET","responseStatusCode":-1,"requestId":"xcdff-1734584072041-fb3aee940b3e","requestUserAgent":"Mozilla/5.0 (iPhone; CPU iPhone OS 18_0 like Mac OS X) AppleWebKit/605.1.15 (KHTML, like Gecko) Version/18.0 Mobile/15E148 Safari/604.1","level":"error","environment":"production","branch":"main","vercelCache":"MISS","type":"lambda","function":"/api/index.py","host":"insta-analysis-d0u1o4xu8-hyunils-projects.vercel.app","deploymentDomain":"insta-analysis-d0u1o4xu8-hyunils-projects.vercel.app","deploymentId":"dpl_GQ3GJcyTnQmKqVYxKjT9F1rXMZ7B","durationMs":-1,"region":"iad1","maxMemoryUsed":-1,"memorySize":-1,"message":"ERROR:api.index:Import 오류: cannot import name 'OpenAI' from 'openai' (/var/task/openai/__init__.py)\nERROR:api.index:현재 Python 경로: ['/var/task', '/var/lang/lib/python312.zip', '/var/lang/lib/python3.12', '/var/lang/lib/python3.12/lib-dynload', '/var/lang/lib/python3.12/site-packages']\nTraceback (most recent call last):\nFile \"/var/task/vc__handler__python.py\", line 14, in <module>\n__vc_spec.loader.exec_module(__vc_module)\nFile \"<frozen importlib._bootstrap_external>\", line 995, in exec_module\nFile \"<frozen importlib._bootstrap>\", line 488, in _call_with_frames_removed\nFile \"/var/task/api/index.py\", line 20, in <module>\nfrom analysis.analyzer import ContentAnalyzer\nFile \"/var/task/analysis/analyzer.py\", line 3, in <module>\nfrom openai import OpenAI\nImportError: cannot import name 'OpenAI' from 'openai' (/var/task/openai/__init__.py)\nPython process exited with exit status: 1. The logs above can help with debugging the issue.","projectId":"prj_pdXNpNzcyIALXwyQJfTG9C9mLb6c"},{"TimeUTC":"2024-12-19 04:54:33","timestampInMs":1734584073127,"requestPath":"insta-analysis-d0u1o4xu8-hyunils-projects.vercel.app/favicon.ico","requestMethod":"GET","responseStatusCode":500,"requestId":"xlx4v-1734584073031-4d07e09b62ec","requestUserAgent":"Mozilla/5.0 (Macintosh; Intel Mac OS X 10_15_7) AppleWebKit/537.36 (KHTML, like Gecko) Chrome/131.0.0.0 Safari/537.36","level":"error","environment":"production","branch":"main","vercelCache":"MISS","type":"lambda","function":"/api/index.py","host":"insta-analysis-d0u1o4xu8-hyunils-projects.vercel.app","deploymentDomain":"insta-analysis-d0u1o4xu8-hyunils-projects.vercel.app","deploymentId":"dpl_GQ3GJcyTnQmKqVYxKjT9F1rXMZ7B","durationMs":1485,"region":"iad1","maxMemoryUsed":74,"memorySize":1024,"message":"","projectId":"prj_pdXNpNzcyIALXwyQJfTG9C9mLb6c"},{"TimeUTC":"2024-12-19 04:54:32","timestampInMs":1734584072098,"requestPath":"insta-analysis-d0u1o4xu8-hyunils-projects.vercel.app/favicon.ico","requestMethod":"GET","responseStatusCode":500,"requestId":"xcdff-1734584072041-fb3aee940b3e","requestUserAgent":"Mozilla/5.0 (iPhone; CPU iPhone OS 18_0 like Mac OS X) AppleWebKit/605.1.15 (KHTML, like Gecko) Version/18.0 Mobile/15E148 Safari/604.1","level":"error","environment":"production","branch":"main","vercelCache":"MISS","type":"lambda","function":"/api/index.py","host":"insta-analysis-d0u1o4xu8-hyunils-projects.vercel.app","deploymentDomain":"insta-analysis-d0u1o4xu8-hyunils-projects.vercel.app","deploymentId":"dpl_GQ3GJcyTnQmKqVYxKjT9F1rXMZ7B","durationMs":1452,"region":"iad1","maxMemoryUsed":74,"memorySize":1024,"message":"","projectId":"prj_pdXNpNzcyIALXwyQJfTG9C9mLb6c"},{"TimeUTC":"2024-12-19 04:54:30","timestampInMs":1734584070396,"requestPath":"insta-analysis-d0u1o4xu8-hyunils-projects.vercel.app/","requestMethod":"GET","responseStatusCode":-1,"requestId":"5x768-1734584068887-338b93f2fc10","requestUserAgent":"vercel-screenshot/1.0","level":"error","environment":"production","branch":"main","vercelCache":"MISS","type":"lambda","function":"/api/index.py","host":"insta-analysis-d0u1o4xu8-hyunils-projects.vercel.app","deploymentDomain":"insta-analysis-d0u1o4xu8-hyunils-projects.vercel.app","deploymentId":"dpl_GQ3GJcyTnQmKqVYxKjT9F1rXMZ7B","durationMs":-1,"region":"iad1","maxMemoryUsed":-1,"memorySize":-1,"message":"ERROR:api.index:Import 오류: cannot import name 'OpenAI' from 'openai' (/var/task/openai/__init__.py)\nERROR:api.index:현재 Python 경로: ['/var/task', '/var/lang/lib/python312.zip', '/var/lang/lib/python3.12', '/var/lang/lib/python3.12/lib-dynload', '/var/lang/lib/python3.12/site-packages']\nTraceback (most recent call last):\nFile \"/var/task/vc__handler__python.py\", line 14, in <module>\n__vc_spec.loader.exec_module(__vc_module)\nFile \"<frozen importlib._bootstrap_external>\", line 995, in exec_module\nFile \"<frozen importlib._bootstrap>\", line 488, in _call_with_frames_removed\nFile \"/var/task/api/index.py\", line 20, in <module>\nfrom analysis.analyzer import ContentAnalyzer\nFile \"/var/task/analysis/analyzer.py\", line 3, in <module>\nfrom openai import OpenAI\nImportError: cannot import name 'OpenAI' from 'openai' (/var/task/openai/__init__.py)\nPython process exited with exit status: 1. The logs above can help with debugging the issue.","projectId":"prj_pdXNpNzcyIALXwyQJfTG9C9mLb6c"},{"TimeUTC":"2024-12-19 04:54:29","timestampInMs":1734584069966,"requestPath":"insta-analysis-d0u1o4xu8-hyunils-projects.vercel.app/favicon.ico","requestMethod":"GET","responseStatusCode":-1,"requestId":"mm799-1734584068431-7756df1ba95f","requestUserAgent":"Mozilla/5.0 (iPhone; CPU iPhone OS 18_0 like Mac OS X) AppleWebKit/605.1.15 (KHTML, like Gecko) Version/18.0 Mobile/15E148 Safari/604.1","level":"error","environment":"production","branch":"main","vercelCache":"MISS","type":"lambda","function":"/api/index.py","host":"insta-analysis-d0u1o4xu8-hyunils-projects.vercel.app","deploymentDomain":"insta-analysis-d0u1o4xu8-hyunils-projects.vercel.app","deploymentId":"dpl_GQ3GJcyTnQmKqVYxKjT9F1rXMZ7B","durationMs":-1,"region":"iad1","maxMemoryUsed":-1,"memorySize":-1,"message":"ERROR:api.index:Import 오류: cannot import name 'OpenAI' from 'openai' (/var/task/openai/__init__.py)\nERROR:api.index:현재 Python 경로: ['/var/task', '/var/lang/lib/python312.zip', '/var/lang/lib/python3.12', '/var/lang/lib/python3.12/lib-dynload', '/var/lang/lib/python3.12/site-packages']\nTraceback (most recent call last):\nFile \"/var/task/vc__handler__python.py\", line 14, in <module>\n__vc_spec.loader.exec_module(__vc_module)\nFile \"<frozen importlib._bootstrap_external>\", line 995, in exec_module\nFile \"<frozen importlib._bootstrap>\", line 488, in _call_with_frames_removed\nFile \"/var/task/api/index.py\", line 20, in <module>\nfrom analysis.analyzer import ContentAnalyzer\nFile \"/var/task/analysis/analyzer.py\", line 3, in <module>\nfrom openai import OpenAI\nImportError: cannot import name 'OpenAI' from 'openai' (/var/task/openai/__init__.py)\nPython process exited with exit status: 1. The logs above can help with debugging the issue.","projectId":"prj_pdXNpNzcyIALXwyQJfTG9C9mLb6c"},{"TimeUTC":"2024-12-19 04:54:29","timestampInMs":1734584069860,"requestPath":"insta-analysis-d0u1o4xu8-hyunils-projects.vercel.app/","requestMethod":"GET","responseStatusCode":-1,"requestId":"xlx4v-1734584068037-de302bb00fd2","requestUserAgent":"Mozilla/5.0 (Macintosh; Intel Mac OS X 10_15_7) AppleWebKit/537.36 (KHTML, like Gecko) Chrome/131.0.0.0 Safari/537.36","level":"error","environment":"production","branch":"main","vercelCache":"MISS","type":"lambda","function":"/api/index.py","host":"insta-analysis-d0u1o4xu8-hyunils-projects.vercel.app","deploymentDomain":"insta-analysis-d0u1o4xu8-hyunils-projects.vercel.app","deploymentId":"dpl_GQ3GJcyTnQmKqVYxKjT9F1rXMZ7B","durationMs":-1,"region":"iad1","maxMemoryUsed":-1,"memorySize":-1,"message":"ERROR:api.index:Import 오류: cannot import name 'OpenAI' from 'openai' (/var/task/openai/__init__.py)\nERROR:api.index:현재 Python 경로: ['/var/task', '/var/lang/lib/python312.zip', '/var/lang/lib/python3.12', '/var/lang/lib/python3.12/lib-dynload', '/var/lang/lib/python3.12/site-packages']\nTraceback (most recent call last):\nFile \"/var/task/vc__handler__python.py\", line 14, in <module>\n__vc_spec.loader.exec_module(__vc_module)\nFile \"<frozen importlib._bootstrap_external>\", line 995, in exec_module\nFile \"<frozen importlib._bootstrap>\", line 488, in _call_with_frames_removed\nFile \"/var/task/api/index.py\", line 20, in <module>\nfrom analysis.analyzer import ContentAnalyzer\nFile \"/var/task/analysis/analyzer.py\", line 3, in <module>\nfrom openai import OpenAI\nImportError: cannot import name 'OpenAI' from 'openai' (/var/task/openai/__init__.py)\nPython process exited with exit status: 1. The logs above can help with debugging the issue.","projectId":"prj_pdXNpNzcyIALXwyQJfTG9C9mLb6c"},{"TimeUTC":"2024-12-19 04:54:29","timestampInMs":1734584069423,"requestPath":"insta-analysis-d0u1o4xu8-hyunils-projects.vercel.app/","requestMethod":"GET","responseStatusCode":-1,"requestId":"rxhzr-1734584067827-d2df3aeeb181","requestUserAgent":"Mozilla/5.0 (iPhone; CPU iPhone OS 18_0 like Mac OS X) AppleWebKit/605.1.15 (KHTML, like Gecko) Version/18.0 Mobile/15E148 Safari/604.1","level":"error","environment":"production","branch":"main","vercelCache":"MISS","type":"lambda","function":"/api/index.py","host":"insta-analysis-d0u1o4xu8-hyunils-projects.vercel.app","deploymentDomain":"insta-analysis-d0u1o4xu8-hyunils-projects.vercel.app","deploymentId":"dpl_GQ3GJcyTnQmKqVYxKjT9F1rXMZ7B","durationMs":-1,"region":"iad1","maxMemoryUsed":-1,"memorySize":-1,"message":"ERROR:api.index:Import 오류: cannot import name 'OpenAI' from 'openai' (/var/task/openai/__init__.py)\nERROR:api.index:현재 Python 경로: ['/var/task', '/var/lang/lib/python312.zip', '/var/lang/lib/python3.12', '/var/lang/lib/python3.12/lib-dynload', '/var/lang/lib/python3.12/site-packages']\nTraceback (most recent call last):\nFile \"/var/task/vc__handler__python.py\", line 14, in <module>\n__vc_spec.loader.exec_module(__vc_module)\nFile \"<frozen importlib._bootstrap_external>\", line 995, in exec_module\nFile \"<frozen importlib._bootstrap>\", line 488, in _call_with_frames_removed\nFile \"/var/task/api/index.py\", line 20, in <module>\nfrom analysis.analyzer import ContentAnalyzer\nFile \"/var/task/analysis/analyzer.py\", line 3, in <module>\nfrom openai import OpenAI\nImportError: cannot import name 'OpenAI' from 'openai' (/var/task/openai/__init__.py)\nPython process exited with exit status: 1. The logs above can help with debugging the issue.","projectId":"prj_pdXNpNzcyIALXwyQJfTG9C9mLb6c"},{"TimeUTC":"2024-12-19 04:54:29","timestampInMs":1734584069276,"requestPath":"insta-analysis-d0u1o4xu8-hyunils-projects.vercel.app/","requestMethod":"GET","responseStatusCode":-1,"requestId":"swhkf-1734584067714-23e506163ad2","requestUserAgent":"vercel-screenshot/1.0","level":"error","environment":"production","branch":"main","vercelCache":"MISS","type":"lambda","function":"/api/index.py","host":"insta-analysis-d0u1o4xu8-hyunils-projects.vercel.app","deploymentDomain":"insta-analysis-d0u1o4xu8-hyunils-projects.vercel.app","deploymentId":"dpl_GQ3GJcyTnQmKqVYxKjT9F1rXMZ7B","durationMs":-1,"region":"iad1","maxMemoryUsed":-1,"memorySize":-1,"message":"ERROR:api.index:Import 오류: cannot import name 'OpenAI' from 'openai' (/var/task/openai/__init__.py)\nERROR:api.index:현재 Python 경로: ['/var/task', '/var/lang/lib/python312.zip', '/var/lang/lib/python3.12', '/var/lang/lib/python3.12/lib-dynload', '/var/lang/lib/python3.12/site-packages']\nTraceback (most recent call last):\nFile \"/var/task/vc__handler__python.py\", line 14, in <module>\n__vc_spec.loader.exec_module(__vc_module)\nFile \"<frozen importlib._bootstrap_external>\", line 995, in exec_module\nFile \"<frozen importlib._bootstrap>\", line 488, in _call_with_frames_removed\nFile \"/var/task/api/index.py\", line 20, in <module>\nfrom analysis.analyzer import ContentAnalyzer\nFile \"/var/task/analysis/analyzer.py\", line 3, in <module>\nfrom openai import OpenAI\nImportError: cannot import name 'OpenAI' from 'openai' (/var/task/openai/__init__.py)\nPython process exited with exit status: 1. The logs above can help with debugging the issue.","projectId":"prj_pdXNpNzcyIALXwyQJfTG9C9mLb6c"},{"TimeUTC":"2024-12-19 04:54:29","timestampInMs":1734584069141,"requestPath":"insta-analysis-d0u1o4xu8-hyunils-projects.vercel.app/","requestMethod":"GET","responseStatusCode":-1,"requestId":"j4n8n-1734584067548-1c3cbd9be006","requestUserAgent":"vercel-screenshot/1.0","level":"error","environment":"production","branch":"main","vercelCache":"MISS","type":"lambda","function":"/api/index.py","host":"insta-analysis-d0u1o4xu8-hyunils-projects.vercel.app","deploymentDomain":"insta-analysis-d0u1o4xu8-hyunils-projects.vercel.app","deploymentId":"dpl_GQ3GJcyTnQmKqVYxKjT9F1rXMZ7B","durationMs":-1,"region":"iad1","maxMemoryUsed":-1,"memorySize":-1,"message":"ERROR:api.index:Import 오류: cannot import name 'OpenAI' from 'openai' (/var/task/openai/__init__.py)\nERROR:api.index:현재 Python 경로: ['/var/task', '/var/lang/lib/python312.zip', '/var/lang/lib/python3.12', '/var/lang/lib/python3.12/lib-dynload', '/var/lang/lib/python3.12/site-packages']\nTraceback (most recent call last):\nFile \"/var/task/vc__handler__python.py\", line 14, in <module>\n__vc_spec.loader.exec_module(__vc_module)\nFile \"<frozen importlib._bootstrap_external>\", line 995, in exec_module\nFile \"<frozen importlib._bootstrap>\", line 488, in _call_with_frames_removed\nFile \"/var/task/api/index.py\", line 20, in <module>\nfrom analysis.analyzer import ContentAnalyzer\nFile \"/var/task/analysis/analyzer.py\", line 3, in <module>\nfrom openai import OpenAI\nImportError: cannot import name 'OpenAI' from 'openai' (/var/task/openai/__init__.py)\nPython process exited with exit status: 1. The logs above can help with debugging the issue.","projectId":"prj_pdXNpNzcyIALXwyQJfTG9C9mLb6c"},{"TimeUTC":"2024-12-19 04:54:28","timestampInMs":1734584068967,"requestPath":"insta-analysis-d0u1o4xu8-hyunils-projects.vercel.app/","requestMethod":"GET","responseStatusCode":-1,"requestId":"n5xl7-1734584067388-979add5b934f","requestUserAgent":"vercel-screenshot/1.0","level":"error","environment":"production","branch":"main","vercelCache":"MISS","type":"lambda","function":"/api/index.py","host":"insta-analysis-d0u1o4xu8-hyunils-projects.vercel.app","deploymentDomain":"insta-analysis-d0u1o4xu8-hyunils-projects.vercel.app","deploymentId":"dpl_GQ3GJcyTnQmKqVYxKjT9F1rXMZ7B","durationMs":-1,"region":"iad1","maxMemoryUsed":-1,"memorySize":-1,"message":"ERROR:api.index:Import 오류: cannot import name 'OpenAI' from 'openai' (/var/task/openai/__init__.py)\nERROR:api.index:현재 Python 경로: ['/var/task', '/var/lang/lib/python312.zip', '/var/lang/lib/python3.12', '/var/lang/lib/python3.12/lib-dynload', '/var/lang/lib/python3.12/site-packages']\nTraceback (most recent call last):\nFile \"/var/task/vc__handler__python.py\", line 14, in <module>\n__vc_spec.loader.exec_module(__vc_module)\nFile \"<frozen importlib._bootstrap_external>\", line 995, in exec_module\nFile \"<frozen importlib._bootstrap>\", line 488, in _call_with_frames_removed\nFile \"/var/task/api/index.py\", line 20, in <module>\nfrom analysis.analyzer import ContentAnalyzer\nFile \"/var/task/analysis/analyzer.py\", line 3, in <module>\nfrom openai import OpenAI\nImportError: cannot import name 'OpenAI' from 'openai' (/var/task/openai/__init__.py)\nPython process exited with exit status: 1. The logs above can help with debugging the issue.","projectId":"prj_pdXNpNzcyIALXwyQJfTG9C9mLb6c"},{"TimeUTC":"2024-12-19 04:54:28","timestampInMs":1734584068924,"requestPath":"insta-analysis-d0u1o4xu8-hyunils-projects.vercel.app/","requestMethod":"GET","responseStatusCode":500,"requestId":"5x768-1734584068887-338b93f2fc10","requestUserAgent":"vercel-screenshot/1.0","level":"error","environment":"production","branch":"main","vercelCache":"MISS","type":"lambda","function":"/api/index.py","host":"insta-analysis-d0u1o4xu8-hyunils-projects.vercel.app","deploymentDomain":"insta-analysis-d0u1o4xu8-hyunils-projects.vercel.app","deploymentId":"dpl_GQ3GJcyTnQmKqVYxKjT9F1rXMZ7B","durationMs":1457,"region":"iad1","maxMemoryUsed":73,"memorySize":1024,"message":"","projectId":"prj_pdXNpNzcyIALXwyQJfTG9C9mLb6c"},{"TimeUTC":"2024-12-19 04:54:28","timestampInMs":1734584068466,"requestPath":"insta-analysis-d0u1o4xu8-hyunils-projects.vercel.app/favicon.ico","requestMethod":"GET","responseStatusCode":500,"requestId":"mm799-1734584068431-7756df1ba95f","requestUserAgent":"Mozilla/5.0 (iPhone; CPU iPhone OS 18_0 like Mac OS X) AppleWebKit/605.1.15 (KHTML, like Gecko) Version/18.0 Mobile/15E148 Safari/604.1","level":"error","environment":"production","branch":"main","vercelCache":"MISS","type":"lambda","function":"/api/index.py","host":"insta-analysis-d0u1o4xu8-hyunils-projects.vercel.app","deploymentDomain":"insta-analysis-d0u1o4xu8-hyunils-projects.vercel.app","deploymentId":"dpl_GQ3GJcyTnQmKqVYxKjT9F1rXMZ7B","durationMs":1485,"region":"iad1","maxMemoryUsed":74,"memorySize":1024,"message":"","projectId":"prj_pdXNpNzcyIALXwyQJfTG9C9mLb6c"},{"TimeUTC":"2024-12-19 04:54:28","timestampInMs":1734584068331,"requestPath":"insta-analysis-d0u1o4xu8-hyunils-projects.vercel.app/","requestMethod":"GET","responseStatusCode":500,"requestId":"xlx4v-1734584068037-de302bb00fd2","requestUserAgent":"Mozilla/5.0 (Macintosh; Intel Mac OS X 10_15_7) AppleWebKit/537.36 (KHTML, like Gecko) Chrome/131.0.0.0 Safari/537.36","level":"error","environment":"production","branch":"main","vercelCache":"MISS","type":"lambda","function":"/api/index.py","host":"insta-analysis-d0u1o4xu8-hyunils-projects.vercel.app","deploymentDomain":"insta-analysis-d0u1o4xu8-hyunils-projects.vercel.app","deploymentId":"dpl_GQ3GJcyTnQmKqVYxKjT9F1rXMZ7B","durationMs":1513,"region":"iad1","maxMemoryUsed":74,"memorySize":1024,"message":"","projectId":"prj_pdXNpNzcyIALXwyQJfTG9C9mLb6c"},{"TimeUTC":"2024-12-19 04:54:27","timestampInMs":1734584067865,"requestPath":"insta-analysis-d0u1o4xu8-hyunils-projects.vercel.app/","requestMethod":"GET","responseStatusCode":500,"requestId":"rxhzr-1734584067827-d2df3aeeb181","requestUserAgent":"Mozilla/5.0 (iPhone; CPU iPhone OS 18_0 like Mac OS X) AppleWebKit/605.1.15 (KHTML, like Gecko) Version/18.0 Mobile/15E148 Safari/604.1","level":"error","environment":"production","branch":"main","vercelCache":"MISS","type":"lambda","function":"/api/index.py","host":"insta-analysis-d0u1o4xu8-hyunils-projects.vercel.app","deploymentDomain":"insta-analysis-d0u1o4xu8-hyunils-projects.vercel.app","deploymentId":"dpl_GQ3GJcyTnQmKqVYxKjT9F1rXMZ7B","durationMs":1541,"region":"iad1","maxMemoryUsed":74,"memorySize":1024,"message":"","projectId":"prj_pdXNpNzcyIALXwyQJfTG9C9mLb6c"},{"TimeUTC":"2024-12-19 04:54:27","timestampInMs":1734584067752,"requestPath":"insta-analysis-d0u1o4xu8-hyunils-projects.vercel.app/","requestMethod":"GET","responseStatusCode":500,"requestId":"swhkf-1734584067714-23e506163ad2","requestUserAgent":"vercel-screenshot/1.0","level":"error","environment":"production","branch":"main","vercelCache":"MISS","type":"lambda","function":"/api/index.py","host":"insta-analysis-d0u1o4xu8-hyunils-projects.vercel.app","deploymentDomain":"insta-analysis-d0u1o4xu8-hyunils-projects.vercel.app","deploymentId":"dpl_GQ3GJcyTnQmKqVYxKjT9F1rXMZ7B","durationMs":1512,"region":"iad1","maxMemoryUsed":74,"memorySize":1024,"message":"","projectId":"prj_pdXNpNzcyIALXwyQJfTG9C9mLb6c"},{"TimeUTC":"2024-12-19 04:54:27","timestampInMs":1734584067585,"requestPath":"insta-analysis-d0u1o4xu8-hyunils-projects.vercel.app/","requestMethod":"GET","responseStatusCode":500,"requestId":"j4n8n-1734584067548-1c3cbd9be006","requestUserAgent":"vercel-screenshot/1.0","level":"error","environment":"production","branch":"main","vercelCache":"MISS","type":"lambda","function":"/api/index.py","host":"insta-analysis-d0u1o4xu8-hyunils-projects.vercel.app","deploymentDomain":"insta-analysis-d0u1o4xu8-hyunils-projects.vercel.app","deploymentId":"dpl_GQ3GJcyTnQmKqVYxKjT9F1rXMZ7B","durationMs":1540,"region":"iad1","maxMemoryUsed":74,"memorySize":1024,"message":"","projectId":"prj_pdXNpNzcyIALXwyQJfTG9C9mLb6c"},{"TimeUTC":"2024-12-19 04:54:27","timestampInMs":1734584067429,"requestPath":"insta-analysis-d0u1o4xu8-hyunils-projects.vercel.app/","requestMethod":"GET","responseStatusCode":500,"requestId":"n5xl7-1734584067388-979add5b934f","requestUserAgent":"vercel-screenshot/1.0","level":"error","environment":"production","branch":"main","vercelCache":"MISS","type":"lambda","function":"/api/index.py","host":"insta-analysis-d0u1o4xu8-hyunils-projects.vercel.app","deploymentDomain":"insta-analysis-d0u1o4xu8-hyunils-projects.vercel.app","deploymentId":"dpl_GQ3GJcyTnQmKqVYxKjT9F1rXMZ7B","durationMs":1522,"region":"iad1","maxMemoryUsed":74,"memorySize":1024,"message":"","projectId":"prj_pdXNpNzcyIALXwyQJfTG9C9mLb6c"},{"TimeUTC":"2024-12-19 04:54:27","timestampInMs":1734584067342,"requestPath":"insta-analysis-d0u1o4xu8-hyunils-projects.vercel.app/favicon.ico","requestMethod":"GET","responseStatusCode":-1,"requestId":"hstl6-1734584065740-8a697e076a1f","requestUserAgent":"Mozilla/5.0 (iPhone; CPU iPhone OS 18_0 like Mac OS X) AppleWebKit/605.1.15 (KHTML, like Gecko) Version/18.0 Mobile/15E148 Safari/604.1","level":"error","environment":"production","branch":"main","vercelCache":"MISS","type":"lambda","function":"/api/index.py","host":"insta-analysis-d0u1o4xu8-hyunils-projects.vercel.app","deploymentDomain":"insta-analysis-d0u1o4xu8-hyunils-projects.vercel.app","deploymentId":"dpl_GQ3GJcyTnQmKqVYxKjT9F1rXMZ7B","durationMs":-1,"region":"iad1","maxMemoryUsed":-1,"memorySize":-1,"message":"ERROR:api.index:Import 오류: cannot import name 'OpenAI' from 'openai' (/var/task/openai/__init__.py)\nERROR:api.index:현재 Python 경로: ['/var/task', '/var/lang/lib/python312.zip', '/var/lang/lib/python3.12', '/var/lang/lib/python3.12/lib-dynload', '/var/lang/lib/python3.12/site-packages']\nTraceback (most recent call last):\nFile \"/var/task/vc__handler__python.py\", line 14, in <module>\n__vc_spec.loader.exec_module(__vc_module)\nFile \"<frozen importlib._bootstrap_external>\", line 995, in exec_module\nFile \"<frozen importlib._bootstrap>\", line 488, in _call_with_frames_removed\nFile \"/var/task/api/index.py\", line 20, in <module>\nfrom analysis.analyzer import ContentAnalyzer\nFile \"/var/task/analysis/analyzer.py\", line 3, in <module>\nfrom openai import OpenAI\nImportError: cannot import name 'OpenAI' from 'openai' (/var/task/openai/__init__.py)\nPython process exited with exit status: 1. The logs above can help with debugging the issue.","projectId":"prj_pdXNpNzcyIALXwyQJfTG9C9mLb6c"},{"TimeUTC":"2024-12-19 04:54:26","timestampInMs":1734584066758,"requestPath":"insta-analysis-d0u1o4xu8-hyunils-projects.vercel.app/","requestMethod":"GET","responseStatusCode":-1,"requestId":"c44rh-1734584065174-d644fb311b63","requestUserAgent":"vercel-screenshot/1.0","level":"error","environment":"production","branch":"main","vercelCache":"MISS","type":"lambda","function":"/api/index.py","host":"insta-analysis-d0u1o4xu8-hyunils-projects.vercel.app","deploymentDomain":"insta-analysis-d0u1o4xu8-hyunils-projects.vercel.app","deploymentId":"dpl_GQ3GJcyTnQmKqVYxKjT9F1rXMZ7B","durationMs":-1,"region":"iad1","maxMemoryUsed":-1,"memorySize":-1,"message":"ERROR:api.index:Import 오류: cannot import name 'OpenAI' from 'openai' (/var/task/openai/__init__.py)\nERROR:api.index:현재 Python 경로: ['/var/task', '/var/lang/lib/python312.zip', '/var/lang/lib/python3.12', '/var/lang/lib/python3.12/lib-dynload', '/var/lang/lib/python3.12/site-packages']\nTraceback (most recent call last):\nFile \"/var/task/vc__handler__python.py\", line 14, in <module>\n__vc_spec.loader.exec_module(__vc_module)\nFile \"<frozen importlib._bootstrap_external>\", line 995, in exec_module\nFile \"<frozen importlib._bootstrap>\", line 488, in _call_with_frames_removed\nFile \"/var/task/api/index.py\", line 20, in <module>\nfrom analysis.analyzer import ContentAnalyzer\nFile \"/var/task/analysis/analyzer.py\", line 3, in <module>\nfrom openai import OpenAI\nImportError: cannot import name 'OpenAI' from 'openai' (/var/task/openai/__init__.py)\nPython process exited with exit status: 1. The logs above can help with debugging the issue.","projectId":"prj_pdXNpNzcyIALXwyQJfTG9C9mLb6c"},{"TimeUTC":"2024-12-19 04:54:25","timestampInMs":1734584065778,"requestPath":"insta-analysis-d0u1o4xu8-hyunils-projects.vercel.app/favicon.ico","requestMethod":"GET","responseStatusCode":500,"requestId":"hstl6-1734584065740-8a697e076a1f","requestUserAgent":"Mozilla/5.0 (iPhone; CPU iPhone OS 18_0 like Mac OS X) AppleWebKit/605.1.15 (KHTML, like Gecko) Version/18.0 Mobile/15E148 Safari/604.1","level":"error","environment":"production","branch":"main","vercelCache":"MISS","type":"lambda","function":"/api/index.py","host":"insta-analysis-d0u1o4xu8-hyunils-projects.vercel.app","deploymentDomain":"insta-analysis-d0u1o4xu8-hyunils-projects.vercel.app","deploymentId":"dpl_GQ3GJcyTnQmKqVYxKjT9F1rXMZ7B","durationMs":1550,"region":"iad1","maxMemoryUsed":74,"memorySize":1024,"message":"","projectId":"prj_pdXNpNzcyIALXwyQJfTG9C9mLb6c"},{"TimeUTC":"2024-12-19 04:54:25","timestampInMs":1734584065764,"requestPath":"insta-analysis-d0u1o4xu8-hyunils-projects.vercel.app/","requestMethod":"GET","responseStatusCode":-1,"requestId":"v4tgt-1734584064214-f356ef04151a","requestUserAgent":"Mozilla/5.0 (iPhone; CPU iPhone OS 18_0 like Mac OS X) AppleWebKit/605.1.15 (KHTML, like Gecko) Version/18.0 Mobile/15E148 Safari/604.1","level":"error","environment":"production","branch":"main","vercelCache":"MISS","type":"lambda","function":"/api/index.py","host":"insta-analysis-d0u1o4xu8-hyunils-projects.vercel.app","deploymentDomain":"insta-analysis-d0u1o4xu8-hyunils-projects.vercel.app","deploymentId":"dpl_GQ3GJcyTnQmKqVYxKjT9F1rXMZ7B","durationMs":-1,"region":"iad1","maxMemoryUsed":-1,"memorySize":-1,"message":"ERROR:api.index:Import 오류: cannot import name 'OpenAI' from 'openai' (/var/task/openai/__init__.py)\nERROR:api.index:현재 Python 경로: ['/var/task', '/var/lang/lib/python312.zip', '/var/lang/lib/python3.12', '/var/lang/lib/python3.12/lib-dynload', '/var/lang/lib/python3.12/site-packages']\nTraceback (most recent call last):\nFile \"/var/task/vc__handler__python.py\", line 14, in <module>\n__vc_spec.loader.exec_module(__vc_module)\nFile \"<frozen importlib._bootstrap_external>\", line 995, in exec_module\nFile \"<frozen importlib._bootstrap>\", line 488, in _call_with_frames_removed\nFile \"/var/task/api/index.py\", line 20, in <module>\nfrom analysis.analyzer import ContentAnalyzer\nFile \"/var/task/analysis/analyzer.py\", line 3, in <module>\nfrom openai import OpenAI\nImportError: cannot import name 'OpenAI' from 'openai' (/var/task/openai/__init__.py)\nPython process exited with exit status: 1. The logs above can help with debugging the issue.","projectId":"prj_pdXNpNzcyIALXwyQJfTG9C9mLb6c"},{"TimeUTC":"2024-12-19 04:54:25","timestampInMs":1734584065729,"requestPath":"insta-analysis-d0u1o4xu8-hyunils-projects.vercel.app/favicon.ico","requestMethod":"GET","responseStatusCode":-1,"requestId":"pk7tv-1734584064157-d01ff91f25de","requestUserAgent":"vercel-screenshot/1.0","level":"error","environment":"production","branch":"main","vercelCache":"MISS","type":"lambda","function":"/api/index.py","host":"insta-analysis-d0u1o4xu8-hyunils-projects.vercel.app","deploymentDomain":"insta-analysis-d0u1o4xu8-hyunils-projects.vercel.app","deploymentId":"dpl_GQ3GJcyTnQmKqVYxKjT9F1rXMZ7B","durationMs":-1,"region":"iad1","maxMemoryUsed":-1,"memorySize":-1,"message":"ERROR:api.index:Import 오류: cannot import name 'OpenAI' from 'openai' (/var/task/openai/__init__.py)\nERROR:api.index:현재 Python 경로: ['/var/task', '/var/lang/lib/python312.zip', '/var/lang/lib/python3.12', '/var/lang/lib/python3.12/lib-dynload', '/var/lang/lib/python3.12/site-packages']\nTraceback (most recent call last):\nFile \"/var/task/vc__handler__python.py\", line 14, in <module>\n__vc_spec.loader.exec_module(__vc_module)\nFile \"<frozen importlib._bootstrap_external>\", line 995, in exec_module\nFile \"<frozen importlib._bootstrap>\", line 488, in _call_with_frames_removed\nFile \"/var/task/api/index.py\", line 20, in <module>\nfrom analysis.analyzer import ContentAnalyzer\nFile \"/var/task/analysis/analyzer.py\", line 3, in <module>\nfrom openai import OpenAI\nImportError: cannot import name 'OpenAI' from 'openai' (/var/task/openai/__init__.py)\nPython process exited with exit status: 1. The logs above can help with debugging the issue.","projectId":"prj_pdXNpNzcyIALXwyQJfTG9C9mLb6c"},{"TimeUTC":"2024-12-19 04:54:25","timestampInMs":1734584065624,"requestPath":"insta-analysis-d0u1o4xu8-hyunils-projects.vercel.app/","requestMethod":"GET","responseStatusCode":-1,"requestId":"mlhfz-1734584064023-b2086cb1b22f","requestUserAgent":"vercel-screenshot/1.0","level":"error","environment":"production","branch":"main","vercelCache":"MISS","type":"lambda","function":"/api/index.py","host":"insta-analysis-d0u1o4xu8-hyunils-projects.vercel.app","deploymentDomain":"insta-analysis-d0u1o4xu8-hyunils-projects.vercel.app","deploymentId":"dpl_GQ3GJcyTnQmKqVYxKjT9F1rXMZ7B","durationMs":-1,"region":"iad1","maxMemoryUsed":-1,"memorySize":-1,"message":"ERROR:api.index:Import 오류: cannot import name 'OpenAI' from 'openai' (/var/task/openai/__init__.py)\nERROR:api.index:현재 Python 경로: ['/var/task', '/var/lang/lib/python312.zip', '/var/lang/lib/python3.12', '/var/lang/lib/python3.12/lib-dynload', '/var/lang/lib/python3.12/site-packages']\nTraceback (most recent call last):\nFile \"/var/task/vc__handler__python.py\", line 14, in <module>\n__vc_spec.loader.exec_module(__vc_module)\nFile \"<frozen importlib._bootstrap_external>\", line 995, in exec_module\nFile \"<frozen importlib._bootstrap>\", line 488, in _call_with_frames_removed\nFile \"/var/task/api/index.py\", line 20, in <module>\nfrom analysis.analyzer import ContentAnalyzer\nFile \"/var/task/analysis/analyzer.py\", line 3, in <module>\nfrom openai import OpenAI\nImportError: cannot import name 'OpenAI' from 'openai' (/var/task/openai/__init__.py)\nPython process exited with exit status: 1. The logs above can help with debugging the issue.","projectId":"prj_pdXNpNzcyIALXwyQJfTG9C9mLb6c"},{"TimeUTC":"2024-12-19 04:54:25","timestampInMs":1734584065620,"requestPath":"insta-analysis-d0u1o4xu8-hyunils-projects.vercel.app/favicon.ico","requestMethod":"GET","responseStatusCode":-1,"requestId":"s69dv-1734584064004-d80cc09476e6","requestUserAgent":"vercel-screenshot/1.0","level":"error","environment":"production","branch":"main","vercelCache":"MISS","type":"lambda","function":"/api/index.py","host":"insta-analysis-d0u1o4xu8-hyunils-projects.vercel.app","deploymentDomain":"insta-analysis-d0u1o4xu8-hyunils-projects.vercel.app","deploymentId":"dpl_GQ3GJcyTnQmKqVYxKjT9F1rXMZ7B","durationMs":-1,"region":"iad1","maxMemoryUsed":-1,"memorySize":-1,"message":"ERROR:api.index:Import 오류: cannot import name 'OpenAI' from 'openai' (/var/task/openai/__init__.py)\nERROR:api.index:현재 Python 경로: ['/var/task', '/var/lang/lib/python312.zip', '/var/lang/lib/python3.12', '/var/lang/lib/python3.12/lib-dynload', '/var/lang/lib/python3.12/site-packages']\nTraceback (most recent call last):\nFile \"/var/task/vc__handler__python.py\", line 14, in <module>\n__vc_spec.loader.exec_module(__vc_module)\nFile \"<frozen importlib._bootstrap_external>\", line 995, in exec_module\nFile \"<frozen importlib._bootstrap>\", line 488, in _call_with_frames_removed\nFile \"/var/task/api/index.py\", line 20, in <module>\nfrom analysis.analyzer import ContentAnalyzer\nFile \"/var/task/analysis/analyzer.py\", line 3, in <module>\nfrom openai import OpenAI\nImportError: cannot import name 'OpenAI' from 'openai' (/var/task/openai/__init__.py)\nPython process exited with exit status: 1. The logs above can help with debugging the issue.","projectId":"prj_pdXNpNzcyIALXwyQJfTG9C9mLb6c"},{"TimeUTC":"2024-12-19 04:54:25","timestampInMs":1734584065601,"requestPath":"insta-analysis-d0u1o4xu8-hyunils-projects.vercel.app/","requestMethod":"GET","responseStatusCode":-1,"requestId":"sjh6c-1734584064008-38a5fbb83570","requestUserAgent":"Mozilla/5.0 (iPhone; CPU iPhone OS 18_0 like Mac OS X) AppleWebKit/605.1.15 (KHTML, like Gecko) Version/18.0 Mobile/15E148 Safari/604.1","level":"error","environment":"production","branch":"main","vercelCache":"MISS","type":"lambda","function":"/api/index.py","host":"insta-analysis-d0u1o4xu8-hyunils-projects.vercel.app","deploymentDomain":"insta-analysis-d0u1o4xu8-hyunils-projects.vercel.app","deploymentId":"dpl_GQ3GJcyTnQmKqVYxKjT9F1rXMZ7B","durationMs":-1,"region":"iad1","maxMemoryUsed":-1,"memorySize":-1,"message":"ERROR:api.index:Import 오류: cannot import name 'OpenAI' from 'openai' (/var/task/openai/__init__.py)\nERROR:api.index:현재 Python 경로: ['/var/task', '/var/lang/lib/python312.zip', '/var/lang/lib/python3.12', '/var/lang/lib/python3.12/lib-dynload', '/var/lang/lib/python3.12/site-packages']\nTraceback (most recent call last):\nFile \"/var/task/vc__handler__python.py\", line 14, in <module>\n__vc_spec.loader.exec_module(__vc_module)\nFile \"<frozen importlib._bootstrap_external>\", line 995, in exec_module\nFile \"<frozen importlib._bootstrap>\", line 488, in _call_with_frames_removed\nFile \"/var/task/api/index.py\", line 20, in <module>\nfrom analysis.analyzer import ContentAnalyzer\nFile \"/var/task/analysis/analyzer.py\", line 3, in <module>\nfrom openai import OpenAI\nImportError: cannot import name 'OpenAI' from 'openai' (/var/task/openai/__init__.py)\nPython process exited with exit status: 1. The logs above can help with debugging the issue.","projectId":"prj_pdXNpNzcyIALXwyQJfTG9C9mLb6c"},{"TimeUTC":"2024-12-19 04:54:25","timestampInMs":1734584065500,"requestPath":"insta-analysis-d0u1o4xu8-hyunils-projects.vercel.app/","requestMethod":"GET","responseStatusCode":-1,"requestId":"vrdx4-1734584063979-01c9d9417b00","requestUserAgent":"vercel-screenshot/1.0","level":"error","environment":"production","branch":"main","vercelCache":"MISS","type":"lambda","function":"/api/index.py","host":"insta-analysis-d0u1o4xu8-hyunils-projects.vercel.app","deploymentDomain":"insta-analysis-d0u1o4xu8-hyunils-projects.vercel.app","deploymentId":"dpl_GQ3GJcyTnQmKqVYxKjT9F1rXMZ7B","durationMs":-1,"region":"iad1","maxMemoryUsed":-1,"memorySize":-1,"message":"ERROR:api.index:Import 오류: cannot import name 'OpenAI' from 'openai' (/var/task/openai/__init__.py)\nERROR:api.index:현재 Python 경로: ['/var/task', '/var/lang/lib/python312.zip', '/var/lang/lib/python3.12', '/var/lang/lib/python3.12/lib-dynload', '/var/lang/lib/python3.12/site-packages']\nTraceback (most recent call last):\nFile \"/var/task/vc__handler__python.py\", line 14, in <module>\n__vc_spec.loader.exec_module(__vc_module)\nFile \"<frozen importlib._bootstrap_external>\", line 995, in exec_module\nFile \"<frozen importlib._bootstrap>\", line 488, in _call_with_frames_removed\nFile \"/var/task/api/index.py\", line 20, in <module>\nfrom analysis.analyzer import ContentAnalyzer\nFile \"/var/task/analysis/analyzer.py\", line 3, in <module>\nfrom openai import OpenAI\nImportError: cannot import name 'OpenAI' from 'openai' (/var/task/openai/__init__.py)\nPython process exited with exit status: 1. The logs above can help with debugging the issue.","projectId":"prj_pdXNpNzcyIALXwyQJfTG9C9mLb6c"},{"TimeUTC":"2024-12-19 04:54:25","timestampInMs":1734584065271,"requestPath":"insta-analysis-d0u1o4xu8-hyunils-projects.vercel.app/","requestMethod":"GET","responseStatusCode":-1,"requestId":"nqbnl-1734584063670-f5f595659a10","requestUserAgent":"vercel-screenshot/1.0","level":"error","environment":"production","branch":"main","vercelCache":"MISS","type":"lambda","function":"/api/index.py","host":"insta-analysis-d0u1o4xu8-hyunils-projects.vercel.app","deploymentDomain":"insta-analysis-d0u1o4xu8-hyunils-projects.vercel.app","deploymentId":"dpl_GQ3GJcyTnQmKqVYxKjT9F1rXMZ7B","durationMs":-1,"region":"iad1","maxMemoryUsed":-1,"memorySize":-1,"message":"ERROR:api.index:Import 오류: cannot import name 'OpenAI' from 'openai' (/var/task/openai/__init__.py)\nERROR:api.index:현재 Python 경로: ['/var/task', '/var/lang/lib/python312.zip', '/var/lang/lib/python3.12', '/var/lang/lib/python3.12/lib-dynload', '/var/lang/lib/python3.12/site-packages']\nTraceback (most recent call last):\nFile \"/var/task/vc__handler__python.py\", line 14, in <module>\n__vc_spec.loader.exec_module(__vc_module)\nFile \"<frozen importlib._bootstrap_external>\", line 995, in exec_module\nFile \"<frozen importlib._bootstrap>\", line 488, in _call_with_frames_removed\nFile \"/var/task/api/index.py\", line 20, in <module>\nfrom analysis.analyzer import ContentAnalyzer\nFile \"/var/task/analysis/analyzer.py\", line 3, in <module>\nfrom openai import OpenAI\nImportError: cannot import name 'OpenAI' from 'openai' (/var/task/openai/__init__.py)\nPython process exited with exit status: 1. The logs above can help with debugging the issue.","projectId":"prj_pdXNpNzcyIALXwyQJfTG9C9mLb6c"},{"TimeUTC":"2024-12-19 04:54:25","timestampInMs":1734584065212,"requestPath":"insta-analysis-d0u1o4xu8-hyunils-projects.vercel.app/","requestMethod":"GET","responseStatusCode":500,"requestId":"c44rh-1734584065174-d644fb311b63","requestUserAgent":"vercel-screenshot/1.0","level":"error","environment":"production","branch":"main","vercelCache":"MISS","type":"lambda","function":"/api/index.py","host":"insta-analysis-d0u1o4xu8-hyunils-projects.vercel.app","deploymentDomain":"insta-analysis-d0u1o4xu8-hyunils-projects.vercel.app","deploymentId":"dpl_GQ3GJcyTnQmKqVYxKjT9F1rXMZ7B","durationMs":1527,"region":"iad1","maxMemoryUsed":74,"memorySize":1024,"message":"","projectId":"prj_pdXNpNzcyIALXwyQJfTG9C9mLb6c"},{"TimeUTC":"2024-12-19 04:54:24","timestampInMs":1734584064939,"requestPath":"insta-analysis-d0u1o4xu8-hyunils-projects.vercel.app/favicon.ico","requestMethod":"GET","responseStatusCode":-1,"requestId":"5fsdm-1734584063379-a6f7da857e04","requestUserAgent":"vercel-screenshot/1.0","level":"error","environment":"production","branch":"main","vercelCache":"MISS","type":"lambda","function":"/api/index.py","host":"insta-analysis-d0u1o4xu8-hyunils-projects.vercel.app","deploymentDomain":"insta-analysis-d0u1o4xu8-hyunils-projects.vercel.app","deploymentId":"dpl_GQ3GJcyTnQmKqVYxKjT9F1rXMZ7B","durationMs":-1,"region":"iad1","maxMemoryUsed":-1,"memorySize":-1,"message":"ERROR:api.index:Import 오류: cannot import name 'OpenAI' from 'openai' (/var/task/openai/__init__.py)\nERROR:api.index:현재 Python 경로: ['/var/task', '/var/lang/lib/python312.zip', '/var/lang/lib/python3.12', '/var/lang/lib/python3.12/lib-dynload', '/var/lang/lib/python3.12/site-packages']\nTraceback (most recent call last):\nFile \"/var/task/vc__handler__python.py\", line 14, in <module>\n__vc_spec.loader.exec_module(__vc_module)\nFile \"<frozen importlib._bootstrap_external>\", line 995, in exec_module\nFile \"<frozen importlib._bootstrap>\", line 488, in _call_with_frames_removed\nFile \"/var/task/api/index.py\", line 20, in <module>\nfrom analysis.analyzer import ContentAnalyzer\nFile \"/var/task/analysis/analyzer.py\", line 3, in <module>\nfrom openai import OpenAI\nImportError: cannot import name 'OpenAI' from 'openai' (/var/task/openai/__init__.py)\nPython process exited with exit status: 1. The logs above can help with debugging the issue.","projectId":"prj_pdXNpNzcyIALXwyQJfTG9C9mLb6c"},{"TimeUTC":"2024-12-19 04:54:24","timestampInMs":1734584064744,"requestPath":"insta-analysis-d0u1o4xu8-hyunils-projects.vercel.app/favicon.ico","requestMethod":"GET","responseStatusCode":-1,"requestId":"pm6kv-1734584063113-cba9f67ce1fb","requestUserAgent":"vercel-screenshot/1.0","level":"error","environment":"production","branch":"main","vercelCache":"MISS","type":"lambda","function":"/api/index.py","host":"insta-analysis-d0u1o4xu8-hyunils-projects.vercel.app","deploymentDomain":"insta-analysis-d0u1o4xu8-hyunils-projects.vercel.app","deploymentId":"dpl_GQ3GJcyTnQmKqVYxKjT9F1rXMZ7B","durationMs":-1,"region":"iad1","maxMemoryUsed":-1,"memorySize":-1,"message":"ERROR:api.index:Import 오류: cannot import name 'OpenAI' from 'openai' (/var/task/openai/__init__.py)\nERROR:api.index:현재 Python 경로: ['/var/task', '/var/lang/lib/python312.zip', '/var/lang/lib/python3.12', '/var/lang/lib/python3.12/lib-dynload', '/var/lang/lib/python3.12/site-packages']\nTraceback (most recent call last):\nFile \"/var/task/vc__handler__python.py\", line 14, in <module>\n__vc_spec.loader.exec_module(__vc_module)\nFile \"<frozen importlib._bootstrap_external>\", line 995, in exec_module\nFile \"<frozen importlib._bootstrap>\", line 488, in _call_with_frames_removed\nFile \"/var/task/api/index.py\", line 20, in <module>\nfrom analysis.analyzer import ContentAnalyzer\nFile \"/var/task/analysis/analyzer.py\", line 3, in <module>\nfrom openai import OpenAI\nImportError: cannot import name 'OpenAI' from 'openai' (/var/task/openai/__init__.py)\nPython process exited with exit status: 1. The logs above can help with debugging the issue.","projectId":"prj_pdXNpNzcyIALXwyQJfTG9C9mLb6c"},{"TimeUTC":"2024-12-19 04:54:24","timestampInMs":1734584064248,"requestPath":"insta-analysis-d0u1o4xu8-hyunils-projects.vercel.app/","requestMethod":"GET","responseStatusCode":500,"requestId":"v4tgt-1734584064214-f356ef04151a","requestUserAgent":"Mozilla/5.0 (iPhone; CPU iPhone OS 18_0 like Mac OS X) AppleWebKit/605.1.15 (KHTML, like Gecko) Version/18.0 Mobile/15E148 Safari/604.1","level":"error","environment":"production","branch":"main","vercelCache":"MISS","type":"lambda","function":"/api/index.py","host":"insta-analysis-d0u1o4xu8-hyunils-projects.vercel.app","deploymentDomain":"insta-analysis-d0u1o4xu8-hyunils-projects.vercel.app","deploymentId":"dpl_GQ3GJcyTnQmKqVYxKjT9F1rXMZ7B","durationMs":1500,"region":"iad1","maxMemoryUsed":74,"memorySize":1024,"message":"","projectId":"prj_pdXNpNzcyIALXwyQJfTG9C9mLb6c"},{"TimeUTC":"2024-12-19 04:54:24","timestampInMs":1734584064192,"requestPath":"insta-analysis-d0u1o4xu8-hyunils-projects.vercel.app/favicon.ico","requestMethod":"GET","responseStatusCode":500,"requestId":"pk7tv-1734584064157-d01ff91f25de","requestUserAgent":"vercel-screenshot/1.0","level":"error","environment":"production","branch":"main","vercelCache":"MISS","type":"lambda","function":"/api/index.py","host":"insta-analysis-d0u1o4xu8-hyunils-projects.vercel.app","deploymentDomain":"insta-analysis-d0u1o4xu8-hyunils-projects.vercel.app","deploymentId":"dpl_GQ3GJcyTnQmKqVYxKjT9F1rXMZ7B","durationMs":1521,"region":"iad1","maxMemoryUsed":74,"memorySize":1024,"message":"","projectId":"prj_pdXNpNzcyIALXwyQJfTG9C9mLb6c"},{"TimeUTC":"2024-12-19 04:54:24","timestampInMs":1734584064060,"requestPath":"insta-analysis-d0u1o4xu8-hyunils-projects.vercel.app/","requestMethod":"GET","responseStatusCode":500,"requestId":"mlhfz-1734584064023-b2086cb1b22f","requestUserAgent":"vercel-screenshot/1.0","level":"error","environment":"production","branch":"main","vercelCache":"MISS","type":"lambda","function":"/api/index.py","host":"insta-analysis-d0u1o4xu8-hyunils-projects.vercel.app","deploymentDomain":"insta-analysis-d0u1o4xu8-hyunils-projects.vercel.app","deploymentId":"dpl_GQ3GJcyTnQmKqVYxKjT9F1rXMZ7B","durationMs":1548,"region":"iad1","maxMemoryUsed":73,"memorySize":1024,"message":"","projectId":"prj_pdXNpNzcyIALXwyQJfTG9C9mLb6c"},{"TimeUTC":"2024-12-19 04:54:24","timestampInMs":1734584064042,"requestPath":"insta-analysis-d0u1o4xu8-hyunils-projects.vercel.app/","requestMethod":"GET","responseStatusCode":500,"requestId":"sjh6c-1734584064008-38a5fbb83570","requestUserAgent":"Mozilla/5.0 (iPhone; CPU iPhone OS 18_0 like Mac OS X) AppleWebKit/605.1.15 (KHTML, like Gecko) Version/18.0 Mobile/15E148 Safari/604.1","level":"error","environment":"production","branch":"main","vercelCache":"MISS","type":"lambda","function":"/api/index.py","host":"insta-analysis-d0u1o4xu8-hyunils-projects.vercel.app","deploymentDomain":"insta-analysis-d0u1o4xu8-hyunils-projects.vercel.app","deploymentId":"dpl_GQ3GJcyTnQmKqVYxKjT9F1rXMZ7B","durationMs":1542,"region":"iad1","maxMemoryUsed":74,"memorySize":1024,"message":"","projectId":"prj_pdXNpNzcyIALXwyQJfTG9C9mLb6c"},{"TimeUTC":"2024-12-19 04:54:24","timestampInMs":1734584064041,"requestPath":"insta-analysis-d0u1o4xu8-hyunils-projects.vercel.app/favicon.ico","requestMethod":"GET","responseStatusCode":500,"requestId":"s69dv-1734584064004-d80cc09476e6","requestUserAgent":"vercel-screenshot/1.0","level":"error","environment":"production","branch":"main","vercelCache":"MISS","type":"lambda","function":"/api/index.py","host":"insta-analysis-d0u1o4xu8-hyunils-projects.vercel.app","deploymentDomain":"insta-analysis-d0u1o4xu8-hyunils-projects.vercel.app","deploymentId":"dpl_GQ3GJcyTnQmKqVYxKjT9F1rXMZ7B","durationMs":1562,"region":"iad1","maxMemoryUsed":74,"memorySize":1024,"message":"","projectId":"prj_pdXNpNzcyIALXwyQJfTG9C9mLb6c"},{"TimeUTC":"2024-12-19 04:54:24","timestampInMs":1734584064035,"requestPath":"insta-analysis-d0u1o4xu8-hyunils-projects.vercel.app/","requestMethod":"GET","responseStatusCode":-1,"requestId":"swhkf-1734584061275-252feec26232","requestUserAgent":"vercel-screenshot/1.0","level":"error","environment":"production","branch":"main","vercelCache":"MISS","type":"lambda","function":"/api/index.py","host":"insta-analysis-d0u1o4xu8-hyunils-projects.vercel.app","deploymentDomain":"insta-analysis-d0u1o4xu8-hyunils-projects.vercel.app","deploymentId":"dpl_GQ3GJcyTnQmKqVYxKjT9F1rXMZ7B","durationMs":-1,"region":"iad1","maxMemoryUsed":-1,"memorySize":-1,"message":"ERROR:api.index:Import 오류: cannot import name 'OpenAI' from 'openai' (/var/task/openai/__init__.py)\nERROR:api.index:현재 Python 경로: ['/var/task', '/var/lang/lib/python312.zip', '/var/lang/lib/python3.12', '/var/lang/lib/python3.12/lib-dynload', '/var/lang/lib/python3.12/site-packages']\nTraceback (most recent call last):\nFile \"/var/task/vc__handler__python.py\", line 14, in <module>\n__vc_spec.loader.exec_module(__vc_module)\nFile \"<frozen importlib._bootstrap_external>\", line 995, in exec_module\nFile \"<frozen importlib._bootstrap>\", line 488, in _call_with_frames_removed\nFile \"/var/task/api/index.py\", line 20, in <module>\nfrom analysis.analyzer import ContentAnalyzer\nFile \"/var/task/analysis/analyzer.py\", line 3, in <module>\nfrom openai import OpenAI\nImportError: cannot import name 'OpenAI' from 'openai' (/var/task/openai/__init__.py)\nPython process exited with exit status: 1. The logs above can help with debugging the issue.\nERROR:api.index:Import 오류: cannot import name 'OpenAI' from 'openai' (/var/task/openai/__init__.py)\nERROR:api.index:현재 Python 경로: ['/var/task', '/var/lang/lib/python312.zip', '/var/lang/lib/python3.12', '/var/lang/lib/python3.12/lib-dynload', '/var/lang/lib/python3.12/site-packages']\nTraceback (most recent call last):\nFile \"/var/task/vc__handler__python.py\", line 14, in <module>\n__vc_spec.loader.exec_module(__vc_module)\nFile \"<frozen importlib._bootstrap_external>\", line 995, in exec_module\nFile \"<frozen importlib._bootstrap>\", line 488, in _call_with_frames_removed\nFile \"/var/task/api/index.py\", line 20, in <module>\nfrom analysis.analyzer import ContentAnalyzer\nFile \"/var/task/analysis/analyzer.py\", line 3, in <module>\nfrom openai import OpenAI\nImportError: cannot import name 'OpenAI' from 'openai' (/var/task/openai/__init__.py)\nPython process exited with exit status: 1. The logs above can help with debugging the issue.","projectId":"prj_pdXNpNzcyIALXwyQJfTG9C9mLb6c"},{"TimeUTC":"2024-12-19 04:54:24","timestampInMs":1734584064016,"requestPath":"insta-analysis-d0u1o4xu8-hyunils-projects.vercel.app/","requestMethod":"GET","responseStatusCode":500,"requestId":"vrdx4-1734584063979-01c9d9417b00","requestUserAgent":"vercel-screenshot/1.0","level":"error","environment":"production","branch":"main","vercelCache":"MISS","type":"lambda","function":"/api/index.py","host":"insta-analysis-d0u1o4xu8-hyunils-projects.vercel.app","deploymentDomain":"insta-analysis-d0u1o4xu8-hyunils-projects.vercel.app","deploymentId":"dpl_GQ3GJcyTnQmKqVYxKjT9F1rXMZ7B","durationMs":1468,"region":"iad1","maxMemoryUsed":74,"memorySize":1024,"message":"","projectId":"prj_pdXNpNzcyIALXwyQJfTG9C9mLb6c"},{"TimeUTC":"2024-12-19 04:54:23","timestampInMs":1734584063882,"requestPath":"insta-analysis-d0u1o4xu8-hyunils-projects.vercel.app/","requestMethod":"GET","responseStatusCode":-1,"requestId":"gpc5b-1734584061324-c92a69794133","requestUserAgent":"vercel-screenshot/1.0","level":"error","environment":"production","branch":"main","vercelCache":"MISS","type":"lambda","function":"/api/index.py","host":"insta-analysis-d0u1o4xu8-hyunils-projects.vercel.app","deploymentDomain":"insta-analysis-d0u1o4xu8-hyunils-projects.vercel.app","deploymentId":"dpl_GQ3GJcyTnQmKqVYxKjT9F1rXMZ7B","durationMs":-1,"region":"iad1","maxMemoryUsed":-1,"memorySize":-1,"message":"ERROR:api.index:Import 오류: cannot import name 'OpenAI' from 'openai' (/var/task/openai/__init__.py)\nERROR:api.index:현재 Python 경로: ['/var/task', '/var/lang/lib/python312.zip', '/var/lang/lib/python3.12', '/var/lang/lib/python3.12/lib-dynload', '/var/lang/lib/python3.12/site-packages']\nTraceback (most recent call last):\nFile \"/var/task/vc__handler__python.py\", line 14, in <module>\n__vc_spec.loader.exec_module(__vc_module)\nFile \"<frozen importlib._bootstrap_external>\", line 995, in exec_module\nFile \"<frozen importlib._bootstrap>\", line 488, in _call_with_frames_removed\nFile \"/var/task/api/index.py\", line 20, in <module>\nfrom analysis.analyzer import ContentAnalyzer\nFile \"/var/task/analysis/analyzer.py\", line 3, in <module>\nfrom openai import OpenAI\nImportError: cannot import name 'OpenAI' from 'openai' (/var/task/openai/__init__.py)\nPython process exited with exit status: 1. The logs above can help with debugging the issue.\nERROR:api.index:Import 오류: cannot import name 'OpenAI' from 'openai' (/var/task/openai/__init__.py)\nERROR:api.index:현재 Python 경로: ['/var/task', '/var/lang/lib/python312.zip', '/var/lang/lib/python3.12', '/var/lang/lib/python3.12/lib-dynload', '/var/lang/lib/python3.12/site-packages']\nTraceback (most recent call last):\nFile \"/var/task/vc__handler__python.py\", line 14, in <module>\n__vc_spec.loader.exec_module(__vc_module)\nFile \"<frozen importlib._bootstrap_external>\", line 995, in exec_module\nFile \"<frozen importlib._bootstrap>\", line 488, in _call_with_frames_removed\nFile \"/var/task/api/index.py\", line 20, in <module>\nfrom analysis.analyzer import ContentAnalyzer\nFile \"/var/task/analysis/analyzer.py\", line 3, in <module>\nfrom openai import OpenAI\nImportError: cannot import name 'OpenAI' from 'openai' (/var/task/openai/__init__.py)\nPython process exited with exit status: 1. The logs above can help with debugging the issue.","projectId":"prj_pdXNpNzcyIALXwyQJfTG9C9mLb6c"},{"TimeUTC":"2024-12-19 04:54:23","timestampInMs":1734584063768,"requestPath":"insta-analysis-d0u1o4xu8-hyunils-projects.vercel.app/","requestMethod":"GET","responseStatusCode":-1,"requestId":"mzspd-1734584061021-89c7e7805398","requestUserAgent":"vercel-screenshot/1.0","level":"error","environment":"production","branch":"main","vercelCache":"MISS","type":"lambda","function":"/api/index.py","host":"insta-analysis-d0u1o4xu8-hyunils-projects.vercel.app","deploymentDomain":"insta-analysis-d0u1o4xu8-hyunils-projects.vercel.app","deploymentId":"dpl_GQ3GJcyTnQmKqVYxKjT9F1rXMZ7B","durationMs":-1,"region":"iad1","maxMemoryUsed":-1,"memorySize":-1,"message":"ERROR:api.index:Import 오류: cannot import name 'OpenAI' from 'openai' (/var/task/openai/__init__.py)\nERROR:api.index:현재 Python 경로: ['/var/task', '/var/lang/lib/python312.zip', '/var/lang/lib/python3.12', '/var/lang/lib/python3.12/lib-dynload', '/var/lang/lib/python3.12/site-packages']\nTraceback (most recent call last):\nFile \"/var/task/vc__handler__python.py\", line 14, in <module>\n__vc_spec.loader.exec_module(__vc_module)\nFile \"<frozen importlib._bootstrap_external>\", line 995, in exec_module\nFile \"<frozen importlib._bootstrap>\", line 488, in _call_with_frames_removed\nFile \"/var/task/api/index.py\", line 20, in <module>\nfrom analysis.analyzer import ContentAnalyzer\nFile \"/var/task/analysis/analyzer.py\", line 3, in <module>\nfrom openai import OpenAI\nImportError: cannot import name 'OpenAI' from 'openai' (/var/task/openai/__init__.py)\nPython process exited with exit status: 1. The logs above can help with debugging the issue.\nERROR:api.index:Import 오류: cannot import name 'OpenAI' from 'openai' (/var/task/openai/__init__.py)\nERROR:api.index:현재 Python 경로: ['/var/task', '/var/lang/lib/python312.zip', '/var/lang/lib/python3.12', '/var/lang/lib/python3.12/lib-dynload', '/var/lang/lib/python3.12/site-packages']\nTraceback (most recent call last):\nFile \"/var/task/vc__handler__python.py\", line 14, in <module>\n__vc_spec.loader.exec_module(__vc_module)\nFile \"<frozen importlib._bootstrap_external>\", line 995, in exec_module\nFile \"<frozen importlib._bootstrap>\", line 488, in _call_with_frames_removed\nFile \"/var/task/api/index.py\", line 20, in <module>\nfrom analysis.analyzer import ContentAnalyzer\nFile \"/var/task/analysis/analyzer.py\", line 3, in <module>\nfrom openai import OpenAI\nImportError: cannot import name 'OpenAI' from 'openai' (/var/task/openai/__init__.py)\nPython process exited with exit status: 1. The logs above can help with debugging the issue.","projectId":"prj_pdXNpNzcyIALXwyQJfTG9C9mLb6c"},{"TimeUTC":"2024-12-19 04:54:23","timestampInMs":1734584063705,"requestPath":"insta-analysis-d0u1o4xu8-hyunils-projects.vercel.app/","requestMethod":"GET","responseStatusCode":500,"requestId":"nqbnl-1734584063670-f5f595659a10","requestUserAgent":"vercel-screenshot/1.0","level":"error","environment":"production","branch":"main","vercelCache":"MISS","type":"lambda","function":"/api/index.py","host":"insta-analysis-d0u1o4xu8-hyunils-projects.vercel.app","deploymentDomain":"insta-analysis-d0u1o4xu8-hyunils-projects.vercel.app","deploymentId":"dpl_GQ3GJcyTnQmKqVYxKjT9F1rXMZ7B","durationMs":1549,"region":"iad1","maxMemoryUsed":73,"memorySize":1024,"message":"","projectId":"prj_pdXNpNzcyIALXwyQJfTG9C9mLb6c"},{"TimeUTC":"2024-12-19 04:54:23","timestampInMs":1734584063421,"requestPath":"insta-analysis-d0u1o4xu8-hyunils-projects.vercel.app/favicon.ico","requestMethod":"GET","responseStatusCode":500,"requestId":"5fsdm-1734584063379-a6f7da857e04","requestUserAgent":"vercel-screenshot/1.0","level":"error","environment":"production","branch":"main","vercelCache":"MISS","type":"lambda","function":"/api/index.py","host":"insta-analysis-d0u1o4xu8-hyunils-projects.vercel.app","deploymentDomain":"insta-analysis-d0u1o4xu8-hyunils-projects.vercel.app","deploymentId":"dpl_GQ3GJcyTnQmKqVYxKjT9F1rXMZ7B","durationMs":1502,"region":"iad1","maxMemoryUsed":74,"memorySize":1024,"message":"","projectId":"prj_pdXNpNzcyIALXwyQJfTG9C9mLb6c"},{"TimeUTC":"2024-12-19 04:54:23","timestampInMs":1734584063163,"requestPath":"insta-analysis-d0u1o4xu8-hyunils-projects.vercel.app/","requestMethod":"GET","responseStatusCode":-1,"requestId":"clc5c-1734584060275-5877cb9d24e5","requestUserAgent":"Mozilla/5.0 (iPhone; CPU iPhone OS 18_0 like Mac OS X) AppleWebKit/605.1.15 (KHTML, like Gecko) Version/18.0 Mobile/15E148 Safari/604.1","level":"error","environment":"production","branch":"main","vercelCache":"MISS","type":"lambda","function":"/api/index.py","host":"insta-analysis-d0u1o4xu8-hyunils-projects.vercel.app","deploymentDomain":"insta-analysis-d0u1o4xu8-hyunils-projects.vercel.app","deploymentId":"dpl_GQ3GJcyTnQmKqVYxKjT9F1rXMZ7B","durationMs":-1,"region":"iad1","maxMemoryUsed":-1,"memorySize":-1,"message":"ERROR:api.index:Import 오류: cannot import name 'OpenAI' from 'openai' (/var/task/openai/__init__.py)\nERROR:api.index:현재 Python 경로: ['/var/task', '/var/lang/lib/python312.zip', '/var/lang/lib/python3.12', '/var/lang/lib/python3.12/lib-dynload', '/var/lang/lib/python3.12/site-packages']\nTraceback (most recent call last):\nFile \"/var/task/vc__handler__python.py\", line 14, in <module>\n__vc_spec.loader.exec_module(__vc_module)\nFile \"<frozen importlib._bootstrap_external>\", line 995, in exec_module\nFile \"<frozen importlib._bootstrap>\", line 488, in _call_with_frames_removed\nFile \"/var/task/api/index.py\", line 20, in <module>\nfrom analysis.analyzer import ContentAnalyzer\nFile \"/var/task/analysis/analyzer.py\", line 3, in <module>\nfrom openai import OpenAI\nImportError: cannot import name 'OpenAI' from 'openai' (/var/task/openai/__init__.py)\nPython process exited with exit status: 1. The logs above can help with debugging the issue.\nERROR:api.index:Import 오류: cannot import name 'OpenAI' from 'openai' (/var/task/openai/__init__.py)\nERROR:api.index:현재 Python 경로: ['/var/task', '/var/lang/lib/python312.zip', '/var/lang/lib/python3.12', '/var/lang/lib/python3.12/lib-dynload', '/var/lang/lib/python3.12/site-packages']\nTraceback (most recent call last):\nFile \"/var/task/vc__handler__python.py\", line 14, in <module>\n__vc_spec.loader.exec_module(__vc_module)\nFile \"<frozen importlib._bootstrap_external>\", line 995, in exec_module\nFile \"<frozen importlib._bootstrap>\", line 488, in _call_with_frames_removed\nFile \"/var/task/api/index.py\", line 20, in <module>\nfrom analysis.analyzer import ContentAnalyzer\nFile \"/var/task/analysis/analyzer.py\", line 3, in <module>\nfrom openai import OpenAI\nImportError: cannot import name 'OpenAI' from 'openai' (/var/task/openai/__init__.py)\nPython process exited with exit status: 1. The logs above can help with debugging the issue.","projectId":"prj_pdXNpNzcyIALXwyQJfTG9C9mLb6c"},{"TimeUTC":"2024-12-19 04:54:23","timestampInMs":1734584063152,"requestPath":"insta-analysis-d0u1o4xu8-hyunils-projects.vercel.app/favicon.ico","requestMethod":"GET","responseStatusCode":500,"requestId":"pm6kv-1734584063113-cba9f67ce1fb","requestUserAgent":"vercel-screenshot/1.0","level":"error","environment":"production","branch":"main","vercelCache":"MISS","type":"lambda","function":"/api/index.py","host":"insta-analysis-d0u1o4xu8-hyunils-projects.vercel.app","deploymentDomain":"insta-analysis-d0u1o4xu8-hyunils-projects.vercel.app","deploymentId":"dpl_GQ3GJcyTnQmKqVYxKjT9F1rXMZ7B","durationMs":1578,"region":"iad1","maxMemoryUsed":74,"memorySize":1024,"message":"","projectId":"prj_pdXNpNzcyIALXwyQJfTG9C9mLb6c"},{"TimeUTC":"2024-12-19 04:54:23","timestampInMs":1734584063048,"requestPath":"insta-analysis-d0u1o4xu8-hyunils-projects.vercel.app/","requestMethod":"GET","responseStatusCode":-1,"requestId":"f6fpl-1734584059987-f3201e3a3ef2","requestUserAgent":"vercel-screenshot/1.0","level":"error","environment":"production","branch":"main","vercelCache":"MISS","type":"lambda","function":"/api/index.py","host":"insta-analysis-d0u1o4xu8-hyunils-projects.vercel.app","deploymentDomain":"insta-analysis-d0u1o4xu8-hyunils-projects.vercel.app","deploymentId":"dpl_GQ3GJcyTnQmKqVYxKjT9F1rXMZ7B","durationMs":-1,"region":"iad1","maxMemoryUsed":-1,"memorySize":-1,"message":"ERROR:api.index:Import 오류: cannot import name 'OpenAI' from 'openai' (/var/task/openai/__init__.py)\nERROR:api.index:현재 Python 경로: ['/var/task', '/var/lang/lib/python312.zip', '/var/lang/lib/python3.12', '/var/lang/lib/python3.12/lib-dynload', '/var/lang/lib/python3.12/site-packages']\nTraceback (most recent call last):\nFile \"/var/task/vc__handler__python.py\", line 14, in <module>\n__vc_spec.loader.exec_module(__vc_module)\nFile \"<frozen importlib._bootstrap_external>\", line 995, in exec_module\nFile \"<frozen importlib._bootstrap>\", line 488, in _call_with_frames_removed\nFile \"/var/task/api/index.py\", line 20, in <module>\nfrom analysis.analyzer import ContentAnalyzer\nFile \"/var/task/analysis/analyzer.py\", line 3, in <module>\nfrom openai import OpenAI\nImportError: cannot import name 'OpenAI' from 'openai' (/var/task/openai/__init__.py)\nPython process exited with exit status: 1. The logs above can help with debugging the issue.\nERROR:api.index:Import 오류: cannot import name 'OpenAI' from 'openai' (/var/task/openai/__init__.py)\nERROR:api.index:현재 Python 경로: ['/var/task', '/var/lang/lib/python312.zip', '/var/lang/lib/python3.12', '/var/lang/lib/python3.12/lib-dynload', '/var/lang/lib/python3.12/site-packages']\nTraceback (most recent call last):\nFile \"/var/task/vc__handler__python.py\", line 14, in <module>\n__vc_spec.loader.exec_module(__vc_module)\nFile \"<frozen importlib._bootstrap_external>\", line 995, in exec_module\nFile \"<frozen importlib._bootstrap>\", line 488, in _call_with_frames_removed\nFile \"/var/task/api/index.py\", line 20, in <module>\nfrom analysis.analyzer import ContentAnalyzer\nFile \"/var/task/analysis/analyzer.py\", line 3, in <module>\nfrom openai import OpenAI\nImportError: cannot import name 'OpenAI' from 'openai' (/var/task/openai/__init__.py)\nPython process exited with exit status: 1. The logs above can help with debugging the issue.","projectId":"prj_pdXNpNzcyIALXwyQJfTG9C9mLb6c"},{"TimeUTC":"2024-12-19 04:54:22","timestampInMs":1734584062952,"requestPath":"insta-analysis-d0u1o4xu8-hyunils-projects.vercel.app/","requestMethod":"GET","responseStatusCode":-1,"requestId":"gkzvw-1734584060125-bc57502cf8b6","requestUserAgent":"vercel-screenshot/1.0","level":"error","environment":"production","branch":"main","vercelCache":"MISS","type":"lambda","function":"/api/index.py","host":"insta-analysis-d0u1o4xu8-hyunils-projects.vercel.app","deploymentDomain":"insta-analysis-d0u1o4xu8-hyunils-projects.vercel.app","deploymentId":"dpl_GQ3GJcyTnQmKqVYxKjT9F1rXMZ7B","durationMs":-1,"region":"iad1","maxMemoryUsed":-1,"memorySize":-1,"message":"ERROR:api.index:Import 오류: cannot import name 'OpenAI' from 'openai' (/var/task/openai/__init__.py)\nERROR:api.index:현재 Python 경로: ['/var/task', '/var/lang/lib/python312.zip', '/var/lang/lib/python3.12', '/var/lang/lib/python3.12/lib-dynload', '/var/lang/lib/python3.12/site-packages']\nTraceback (most recent call last):\nFile \"/var/task/vc__handler__python.py\", line 14, in <module>\n__vc_spec.loader.exec_module(__vc_module)\nFile \"<frozen importlib._bootstrap_external>\", line 995, in exec_module\nFile \"<frozen importlib._bootstrap>\", line 488, in _call_with_frames_removed\nFile \"/var/task/api/index.py\", line 20, in <module>\nfrom analysis.analyzer import ContentAnalyzer\nFile \"/var/task/analysis/analyzer.py\", line 3, in <module>\nfrom openai import OpenAI\nImportError: cannot import name 'OpenAI' from 'openai' (/var/task/openai/__init__.py)\nPython process exited with exit status: 1. The logs above can help with debugging the issue.\nERROR:api.index:Import 오류: cannot import name 'OpenAI' from 'openai' (/var/task/openai/__init__.py)\nERROR:api.index:현재 Python 경로: ['/var/task', '/var/lang/lib/python312.zip', '/var/lang/lib/python3.12', '/var/lang/lib/python3.12/lib-dynload', '/var/lang/lib/python3.12/site-packages']\nTraceback (most recent call last):\nFile \"/var/task/vc__handler__python.py\", line 14, in <module>\n__vc_spec.loader.exec_module(__vc_module)\nFile \"<frozen importlib._bootstrap_external>\", line 995, in exec_module\nFile \"<frozen importlib._bootstrap>\", line 488, in _call_with_frames_removed\nFile \"/var/task/api/index.py\", line 20, in <module>\nfrom analysis.analyzer import ContentAnalyzer\nFile \"/var/task/analysis/analyzer.py\", line 3, in <module>\nfrom openai import OpenAI\nImportError: cannot import name 'OpenAI' from 'openai' (/var/task/openai/__init__.py)\nPython process exited with exit status: 1. The logs above can help with debugging the issue.","projectId":"prj_pdXNpNzcyIALXwyQJfTG9C9mLb6c"},{"TimeUTC":"2024-12-19 04:54:22","timestampInMs":1734584062926,"requestPath":"insta-analysis-d0u1o4xu8-hyunils-projects.vercel.app/","requestMethod":"GET","responseStatusCode":-1,"requestId":"j4n8n-1734584060021-64bebfd46ef1","requestUserAgent":"vercel-screenshot/1.0","level":"error","environment":"production","branch":"main","vercelCache":"MISS","type":"lambda","function":"/api/index.py","host":"insta-analysis-d0u1o4xu8-hyunils-projects.vercel.app","deploymentDomain":"insta-analysis-d0u1o4xu8-hyunils-projects.vercel.app","deploymentId":"dpl_GQ3GJcyTnQmKqVYxKjT9F1rXMZ7B","durationMs":-1,"region":"iad1","maxMemoryUsed":-1,"memorySize":-1,"message":"ERROR:api.index:Import 오류: cannot import name 'OpenAI' from 'openai' (/var/task/openai/__init__.py)\nERROR:api.index:현재 Python 경로: ['/var/task', '/var/lang/lib/python312.zip', '/var/lang/lib/python3.12', '/var/lang/lib/python3.12/lib-dynload', '/var/lang/lib/python3.12/site-packages']\nTraceback (most recent call last):\nFile \"/var/task/vc__handler__python.py\", line 14, in <module>\n__vc_spec.loader.exec_module(__vc_module)\nFile \"<frozen importlib._bootstrap_external>\", line 995, in exec_module\nFile \"<frozen importlib._bootstrap>\", line 488, in _call_with_frames_removed\nFile \"/var/task/api/index.py\", line 20, in <module>\nfrom analysis.analyzer import ContentAnalyzer\nFile \"/var/task/analysis/analyzer.py\", line 3, in <module>\nfrom openai import OpenAI\nImportError: cannot import name 'OpenAI' from 'openai' (/var/task/openai/__init__.py)\nPython process exited with exit status: 1. The logs above can help with debugging the issue.\nERROR:api.index:Import 오류: cannot import name 'OpenAI' from 'openai' (/var/task/openai/__init__.py)\nERROR:api.index:현재 Python 경로: ['/var/task', '/var/lang/lib/python312.zip', '/var/lang/lib/python3.12', '/var/lang/lib/python3.12/lib-dynload', '/var/lang/lib/python3.12/site-packages']\nTraceback (most recent call last):\nFile \"/var/task/vc__handler__python.py\", line 14, in <module>\n__vc_spec.loader.exec_module(__vc_module)\nFile \"<frozen importlib._bootstrap_external>\", line 995, in exec_module\nFile \"<frozen importlib._bootstrap>\", line 488, in _call_with_frames_removed\nFile \"/var/task/api/index.py\", line 20, in <module>\nfrom analysis.analyzer import ContentAnalyzer\nFile \"/var/task/analysis/analyzer.py\", line 3, in <module>\nfrom openai import OpenAI\nImportError: cannot import name 'OpenAI' from 'openai' (/var/task/openai/__init__.py)\nPython process exited with exit status: 1. The logs above can help with debugging the issue.","projectId":"prj_pdXNpNzcyIALXwyQJfTG9C9mLb6c"},{"TimeUTC":"2024-12-19 04:54:22","timestampInMs":1734584062917,"requestPath":"insta-analysis-d0u1o4xu8-hyunils-projects.vercel.app/","requestMethod":"GET","responseStatusCode":-1,"requestId":"pm6kv-1734584060202-11ed72dcf462","requestUserAgent":"Mozilla/5.0 (iPhone; CPU iPhone OS 18_0 like Mac OS X) AppleWebKit/605.1.15 (KHTML, like Gecko) Version/18.0 Mobile/15E148 Safari/604.1","level":"error","environment":"production","branch":"main","vercelCache":"MISS","type":"lambda","function":"/api/index.py","host":"insta-analysis-d0u1o4xu8-hyunils-projects.vercel.app","deploymentDomain":"insta-analysis-d0u1o4xu8-hyunils-projects.vercel.app","deploymentId":"dpl_GQ3GJcyTnQmKqVYxKjT9F1rXMZ7B","durationMs":-1,"region":"iad1","maxMemoryUsed":-1,"memorySize":-1,"message":"ERROR:api.index:Import 오류: cannot import name 'OpenAI' from 'openai' (/var/task/openai/__init__.py)\nERROR:api.index:현재 Python 경로: ['/var/task', '/var/lang/lib/python312.zip', '/var/lang/lib/python3.12', '/var/lang/lib/python3.12/lib-dynload', '/var/lang/lib/python3.12/site-packages']\nTraceback (most recent call last):\nFile \"/var/task/vc__handler__python.py\", line 14, in <module>\n__vc_spec.loader.exec_module(__vc_module)\nFile \"<frozen importlib._bootstrap_external>\", line 995, in exec_module\nFile \"<frozen importlib._bootstrap>\", line 488, in _call_with_frames_removed\nFile \"/var/task/api/index.py\", line 20, in <module>\nfrom analysis.analyzer import ContentAnalyzer\nFile \"/var/task/analysis/analyzer.py\", line 3, in <module>\nfrom openai import OpenAI\nImportError: cannot import name 'OpenAI' from 'openai' (/var/task/openai/__init__.py)\nPython process exited with exit status: 1. The logs above can help with debugging the issue.\nERROR:api.index:Import 오류: cannot import name 'OpenAI' from 'openai' (/var/task/openai/__init__.py)\nERROR:api.index:현재 Python 경로: ['/var/task', '/var/lang/lib/python312.zip', '/var/lang/lib/python3.12', '/var/lang/lib/python3.12/lib-dynload', '/var/lang/lib/python3.12/site-packages']\nTraceback (most recent call last):\nFile \"/var/task/vc__handler__python.py\", line 14, in <module>\n__vc_spec.loader.exec_module(__vc_module)\nFile \"<frozen importlib._bootstrap_external>\", line 995, in exec_module\nFile \"<frozen importlib._bootstrap>\", line 488, in _call_with_frames_removed\nFile \"/var/task/api/index.py\", line 20, in <module>\nfrom analysis.analyzer import ContentAnalyzer\nFile \"/var/task/analysis/analyzer.py\", line 3, in <module>\nfrom openai import OpenAI\nImportError: cannot import name 'OpenAI' from 'openai' (/var/task/openai/__init__.py)\nPython process exited with exit status: 1. The logs above can help with debugging the issue.","projectId":"prj_pdXNpNzcyIALXwyQJfTG9C9mLb6c"},{"TimeUTC":"2024-12-19 04:54:22","timestampInMs":1734584062723,"requestPath":"insta-analysis-d0u1o4xu8-hyunils-projects.vercel.app/","requestMethod":"GET","responseStatusCode":-1,"requestId":"bgjjb-1734584059874-aec4890b3e81","requestUserAgent":"vercel-screenshot/1.0","level":"error","environment":"production","branch":"main","vercelCache":"MISS","type":"lambda","function":"/api/index.py","host":"insta-analysis-d0u1o4xu8-hyunils-projects.vercel.app","deploymentDomain":"insta-analysis-d0u1o4xu8-hyunils-projects.vercel.app","deploymentId":"dpl_GQ3GJcyTnQmKqVYxKjT9F1rXMZ7B","durationMs":-1,"region":"iad1","maxMemoryUsed":-1,"memorySize":-1,"message":"ERROR:api.index:Import 오류: cannot import name 'OpenAI' from 'openai' (/var/task/openai/__init__.py)\nERROR:api.index:현재 Python 경로: ['/var/task', '/var/lang/lib/python312.zip', '/var/lang/lib/python3.12', '/var/lang/lib/python3.12/lib-dynload', '/var/lang/lib/python3.12/site-packages']\nTraceback (most recent call last):\nFile \"/var/task/vc__handler__python.py\", line 14, in <module>\n__vc_spec.loader.exec_module(__vc_module)\nFile \"<frozen importlib._bootstrap_external>\", line 995, in exec_module\nFile \"<frozen importlib._bootstrap>\", line 488, in _call_with_frames_removed\nFile \"/var/task/api/index.py\", line 20, in <module>\nfrom analysis.analyzer import ContentAnalyzer\nFile \"/var/task/analysis/analyzer.py\", line 3, in <module>\nfrom openai import OpenAI\nImportError: cannot import name 'OpenAI' from 'openai' (/var/task/openai/__init__.py)\nPython process exited with exit status: 1. The logs above can help with debugging the issue.\nERROR:api.index:Import 오류: cannot import name 'OpenAI' from 'openai' (/var/task/openai/__init__.py)\nERROR:api.index:현재 Python 경로: ['/var/task', '/var/lang/lib/python312.zip', '/var/lang/lib/python3.12', '/var/lang/lib/python3.12/lib-dynload', '/var/lang/lib/python3.12/site-packages']\nTraceback (most recent call last):\nFile \"/var/task/vc__handler__python.py\", line 14, in <module>\n__vc_spec.loader.exec_module(__vc_module)\nFile \"<frozen importlib._bootstrap_external>\", line 995, in exec_module\nFile \"<frozen importlib._bootstrap>\", line 488, in _call_with_frames_removed\nFile \"/var/task/api/index.py\", line 20, in <module>\nfrom analysis.analyzer import ContentAnalyzer\nFile \"/var/task/analysis/analyzer.py\", line 3, in <module>\nfrom openai import OpenAI\nImportError: cannot import name 'OpenAI' from 'openai' (/var/task/openai/__init__.py)\nPython process exited with exit status: 1. The logs above can help with debugging the issue.","projectId":"prj_pdXNpNzcyIALXwyQJfTG9C9mLb6c"},{"TimeUTC":"2024-12-19 04:54:22","timestampInMs":1734584062572,"requestPath":"insta-analysis-d0u1o4xu8-hyunils-projects.vercel.app/","requestMethod":"GET","responseStatusCode":-1,"requestId":"vpskg-1734584060943-c9bff59e28d7","requestUserAgent":"vercel-screenshot/1.0","level":"error","environment":"production","branch":"main","vercelCache":"MISS","type":"lambda","function":"/api/index.py","host":"insta-analysis-d0u1o4xu8-hyunils-projects.vercel.app","deploymentDomain":"insta-analysis-d0u1o4xu8-hyunils-projects.vercel.app","deploymentId":"dpl_GQ3GJcyTnQmKqVYxKjT9F1rXMZ7B","durationMs":-1,"region":"iad1","maxMemoryUsed":-1,"memorySize":-1,"message":"ERROR:api.index:Import 오류: cannot import name 'OpenAI' from 'openai' (/var/task/openai/__init__.py)\nERROR:api.index:현재 Python 경로: ['/var/task', '/var/lang/lib/python312.zip', '/var/lang/lib/python3.12', '/var/lang/lib/python3.12/lib-dynload', '/var/lang/lib/python3.12/site-packages']\nTraceback (most recent call last):\nFile \"/var/task/vc__handler__python.py\", line 14, in <module>\n__vc_spec.loader.exec_module(__vc_module)\nFile \"<frozen importlib._bootstrap_external>\", line 995, in exec_module\nFile \"<frozen importlib._bootstrap>\", line 488, in _call_with_frames_removed\nFile \"/var/task/api/index.py\", line 20, in <module>\nfrom analysis.analyzer import ContentAnalyzer\nFile \"/var/task/analysis/analyzer.py\", line 3, in <module>\nfrom openai import OpenAI\nImportError: cannot import name 'OpenAI' from 'openai' (/var/task/openai/__init__.py)\nPython process exited with exit status: 1. The logs above can help with debugging the issue.","projectId":"prj_pdXNpNzcyIALXwyQJfTG9C9mLb6c"},{"TimeUTC":"2024-12-19 04:54:21","timestampInMs":1734584061368,"requestPath":"insta-analysis-d0u1o4xu8-hyunils-projects.vercel.app/","requestMethod":"GET","responseStatusCode":500,"requestId":"gpc5b-1734584061324-c92a69794133","requestUserAgent":"vercel-screenshot/1.0","level":"error","environment":"production","branch":"main","vercelCache":"MISS","type":"lambda","function":"/api/index.py","host":"insta-analysis-d0u1o4xu8-hyunils-projects.vercel.app","deploymentDomain":"insta-analysis-d0u1o4xu8-hyunils-projects.vercel.app","deploymentId":"dpl_GQ3GJcyTnQmKqVYxKjT9F1rXMZ7B","durationMs":1497,"region":"iad1","maxMemoryUsed":74,"memorySize":1024,"message":"","projectId":"prj_pdXNpNzcyIALXwyQJfTG9C9mLb6c"},{"TimeUTC":"2024-12-19 04:54:21","timestampInMs":1734584061313,"requestPath":"insta-analysis-d0u1o4xu8-hyunils-projects.vercel.app/","requestMethod":"GET","responseStatusCode":500,"requestId":"swhkf-1734584061275-252feec26232","requestUserAgent":"vercel-screenshot/1.0","level":"error","environment":"production","branch":"main","vercelCache":"MISS","type":"lambda","function":"/api/index.py","host":"insta-analysis-d0u1o4xu8-hyunils-projects.vercel.app","deploymentDomain":"insta-analysis-d0u1o4xu8-hyunils-projects.vercel.app","deploymentId":"dpl_GQ3GJcyTnQmKqVYxKjT9F1rXMZ7B","durationMs":1543,"region":"iad1","maxMemoryUsed":74,"memorySize":1024,"message":"","projectId":"prj_pdXNpNzcyIALXwyQJfTG9C9mLb6c"},{"TimeUTC":"2024-12-19 04:54:21","timestampInMs":1734584061062,"requestPath":"insta-analysis-d0u1o4xu8-hyunils-projects.vercel.app/","requestMethod":"GET","responseStatusCode":500,"requestId":"mzspd-1734584061021-89c7e7805398","requestUserAgent":"vercel-screenshot/1.0","level":"error","environment":"production","branch":"main","vercelCache":"MISS","type":"lambda","function":"/api/index.py","host":"insta-analysis-d0u1o4xu8-hyunils-projects.vercel.app","deploymentDomain":"insta-analysis-d0u1o4xu8-hyunils-projects.vercel.app","deploymentId":"dpl_GQ3GJcyTnQmKqVYxKjT9F1rXMZ7B","durationMs":1559,"region":"iad1","maxMemoryUsed":74,"memorySize":1024,"message":"","projectId":"prj_pdXNpNzcyIALXwyQJfTG9C9mLb6c"},{"TimeUTC":"2024-12-19 04:54:20","timestampInMs":1734584060982,"requestPath":"insta-analysis-d0u1o4xu8-hyunils-projects.vercel.app/","requestMethod":"GET","responseStatusCode":500,"requestId":"vpskg-1734584060943-c9bff59e28d7","requestUserAgent":"vercel-screenshot/1.0","level":"error","environment":"production","branch":"main","vercelCache":"MISS","type":"lambda","function":"/api/index.py","host":"insta-analysis-d0u1o4xu8-hyunils-projects.vercel.app","deploymentDomain":"insta-analysis-d0u1o4xu8-hyunils-projects.vercel.app","deploymentId":"dpl_GQ3GJcyTnQmKqVYxKjT9F1rXMZ7B","durationMs":1573,"region":"iad1","maxMemoryUsed":73,"memorySize":1024,"message":"","projectId":"prj_pdXNpNzcyIALXwyQJfTG9C9mLb6c"},{"TimeUTC":"2024-12-19 04:54:20","timestampInMs":1734584060404,"requestPath":"insta-analysis-d0u1o4xu8-hyunils-projects.vercel.app/","requestMethod":"GET","responseStatusCode":500,"requestId":"clc5c-1734584060275-5877cb9d24e5","requestUserAgent":"Mozilla/5.0 (iPhone; CPU iPhone OS 18_0 like Mac OS X) AppleWebKit/605.1.15 (KHTML, like Gecko) Version/18.0 Mobile/15E148 Safari/604.1","level":"error","environment":"production","branch":"main","vercelCache":"MISS","type":"lambda","function":"/api/index.py","host":"insta-analysis-d0u1o4xu8-hyunils-projects.vercel.app","deploymentDomain":"insta-analysis-d0u1o4xu8-hyunils-projects.vercel.app","deploymentId":"dpl_GQ3GJcyTnQmKqVYxKjT9F1rXMZ7B","durationMs":1580,"region":"iad1","maxMemoryUsed":74,"memorySize":1024,"message":"","projectId":"prj_pdXNpNzcyIALXwyQJfTG9C9mLb6c"},{"TimeUTC":"2024-12-19 04:54:20","timestampInMs":1734584060250,"requestPath":"insta-analysis-d0u1o4xu8-hyunils-projects.vercel.app/","requestMethod":"GET","responseStatusCode":500,"requestId":"gkzvw-1734584060125-bc57502cf8b6","requestUserAgent":"vercel-screenshot/1.0","level":"error","environment":"production","branch":"main","vercelCache":"MISS","type":"lambda","function":"/api/index.py","host":"insta-analysis-d0u1o4xu8-hyunils-projects.vercel.app","deploymentDomain":"insta-analysis-d0u1o4xu8-hyunils-projects.vercel.app","deploymentId":"dpl_GQ3GJcyTnQmKqVYxKjT9F1rXMZ7B","durationMs":1550,"region":"iad1","maxMemoryUsed":74,"memorySize":1024,"message":"","projectId":"prj_pdXNpNzcyIALXwyQJfTG9C9mLb6c"},{"TimeUTC":"2024-12-19 04:54:20","timestampInMs":1734584060248,"requestPath":"insta-analysis-d0u1o4xu8-hyunils-projects.vercel.app/","requestMethod":"GET","responseStatusCode":500,"requestId":"pm6kv-1734584060202-11ed72dcf462","requestUserAgent":"Mozilla/5.0 (iPhone; CPU iPhone OS 18_0 like Mac OS X) AppleWebKit/605.1.15 (KHTML, like Gecko) Version/18.0 Mobile/15E148 Safari/604.1","level":"error","environment":"production","branch":"main","vercelCache":"MISS","type":"lambda","function":"/api/index.py","host":"insta-analysis-d0u1o4xu8-hyunils-projects.vercel.app","deploymentDomain":"insta-analysis-d0u1o4xu8-hyunils-projects.vercel.app","deploymentId":"dpl_GQ3GJcyTnQmKqVYxKjT9F1rXMZ7B","durationMs":1551,"region":"iad1","maxMemoryUsed":74,"memorySize":1024,"message":"","projectId":"prj_pdXNpNzcyIALXwyQJfTG9C9mLb6c"},{"TimeUTC":"2024-12-19 04:54:20","timestampInMs":1734584060160,"requestPath":"insta-analysis-d0u1o4xu8-hyunils-projects.vercel.app/","requestMethod":"GET","responseStatusCode":500,"requestId":"j4n8n-1734584060021-64bebfd46ef1","requestUserAgent":"vercel-screenshot/1.0","level":"error","environment":"production","branch":"main","vercelCache":"MISS","type":"lambda","function":"/api/index.py","host":"insta-analysis-d0u1o4xu8-hyunils-projects.vercel.app","deploymentDomain":"insta-analysis-d0u1o4xu8-hyunils-projects.vercel.app","deploymentId":"dpl_GQ3GJcyTnQmKqVYxKjT9F1rXMZ7B","durationMs":1596,"region":"iad1","maxMemoryUsed":74,"memorySize":1024,"message":"","projectId":"prj_pdXNpNzcyIALXwyQJfTG9C9mLb6c"},{"TimeUTC":"2024-12-19 04:54:20","timestampInMs":1734584060124,"requestPath":"insta-analysis-d0u1o4xu8-hyunils-projects.vercel.app/","requestMethod":"GET","responseStatusCode":500,"requestId":"f6fpl-1734584059987-f3201e3a3ef2","requestUserAgent":"vercel-screenshot/1.0","level":"error","environment":"production","branch":"main","vercelCache":"MISS","type":"lambda","function":"/api/index.py","host":"insta-analysis-d0u1o4xu8-hyunils-projects.vercel.app","deploymentDomain":"insta-analysis-d0u1o4xu8-hyunils-projects.vercel.app","deploymentId":"dpl_GQ3GJcyTnQmKqVYxKjT9F1rXMZ7B","durationMs":1670,"region":"iad1","maxMemoryUsed":74,"memorySize":1024,"message":"","projectId":"prj_pdXNpNzcyIALXwyQJfTG9C9mLb6c"},{"TimeUTC":"2024-12-19 04:54:20","timestampInMs":1734584060107,"requestPath":"insta-analysis-d0u1o4xu8-hyunils-projects.vercel.app/","requestMethod":"GET","responseStatusCode":500,"requestId":"bgjjb-1734584059874-aec4890b3e81","requestUserAgent":"vercel-screenshot/1.0","level":"error","environment":"production","branch":"main","vercelCache":"MISS","type":"lambda","function":"/api/index.py","host":"insta-analysis-d0u1o4xu8-hyunils-projects.vercel.app","deploymentDomain":"insta-analysis-d0u1o4xu8-hyunils-projects.vercel.app","deploymentId":"dpl_GQ3GJcyTnQmKqVYxKjT9F1rXMZ7B","durationMs":1497,"region":"iad1","maxMemoryUsed":74,"memorySize":1024,"message":"","projectId":"prj_pdXNpNzcyIALXwyQJfTG9C9mLb6c"}]